Workbook

Sheet Источник_данных
A1: Источник данных и порядок отбора
A2: Открытые данные STATS19 (Department for Transport, Великобритания); агрегирование выполнено Python-скриптом, далее все расчёты — формулами Excel
A4: Набор данных | B4: Road Safety Data (STATS19), Department for Transport — таблица collision (сведения о ДТП)
A5: Страница набора | B5: https://www.data.gov.uk/dataset/cb7ae6f0-4be6-4935-9277-47e5ce24a11f/road-safety-data
A6: Страница публикации | B6: https://www.gov.uk/government/statistics/road-safety-data
A7: Скачанный файл | B7: https://data.dft.gov.uk/road-accidents-safety-data/dft-road-casualty-statistics-collision-1979-latest-published-year.csv
A8: Размер / SHA-256 | B8: 1 534 937 928 байт; 7b80a3a8d9df7b54633a4019e73c8512ca052b166ca2afac0fff4d1448565edc
A9: Справочник кодов | B9: dft-road-casualty-statistics-road-safety-open-dataset-data-guide-2025.xlsx (лист 2024_code_list)
A10: Дата загрузки | B10: 27.10.2026
A11: Лицензия | B11: Open Government Licence v3.0
A12: Источник ВКР | B12: Kaggle «UK Road Safety: Accidents and Vehicles» (выгрузка тех же данных DfT, 2005–2017) — у нас заменён первоисточником
A14: Шаги отбора
A15: Шаг | B15: Условие (поля STATS19) | C15: Записей
A16: 0. Весь файл | B16: 1979–2025, все ДТП с пострадавшими | C16: 9116625
A17: 1. Период | B17: collision_year от 2009 до 2017 | C17: 1306654
A18: 2. Тяжесть | B18: collision_severity = 1 (Fatal — со смертельным исходом) | C18: 15475
A19: 2а. Англия (справочно) | B19: local_authority_ons_district начинается с «E» | C19: 13075
A20: 3. Территория | B20: local_authority_ons_district = E06000052 (local_authority_district = 596, Cornwall; police_force = 50 Devon and Cornwall) | C20: 186
A21: 4. Сельская местность | B21: urban_or_rural_area = 2 (Rural) | C21: 172
A22: 5. Как в ВКР | B22: исключены 2 ДТП января 2009 г. (200950GC2H002, 200950BB2B001), отсутствующие в выгрузке автора ВКР | C22: 170
A24: Контроль
A25: ДТП в выборке (лист ДТП_Корнуолл) | C25: =SUM(ДТП_Корнуолл!S5:S176) -> 170
A26: Пострадавших в выборке | C26: =SUMIFS(ДТП_Корнуолл!O5:O176,ДТП_Корнуолл!S5:S176,1) -> 424
A27: В ВКР: 170 ДТП, 424 пострадавших (в тексте ВКР — «погибли 424 человека»; фактически это number_of_casualties — все пострадавшие)
A29: Почему именно Корнуолл
A30: На рис. 2.4 ВКР видны номера ДТП 200950AH2E013, 200950AH2E017, 200950AH2T013, 200950AY2D003, 200950AY2E005.
A31: В STATS19 все пять — Cornwall (E06000052), Rural, Fatal. Тот же фильтр по всем годам даёт 172 ДТП / 426 пострадавших;
A32: без двух январских ДТП 2009 г. (у автора первое ДТП — 21.02.2009) — ровно 170 ДТП / 424 пострадавших, как в ВКР.
A33: Классы дорог не фильтровались: в выборку входят A, B, C и 10 ДТП на неклассифицированных дорогах (автор пишет «A, B, C»).
A35: Кодирование факторов (как в ВКР)
A36: Фактор ВКР | B36: Поле STATS19 и коды | C36: Код 1 / код 0
A37: Pr — «праздник» (выходные) | B37: day_of_week: 1 Sunday, 2 Monday, …, 6 Friday, 7 Saturday | C37: 1 — пт, сб, вс (6, 7, 1); 0 — пн–чт
A38: Cv — освещённость | B38: light_conditions: 1 Daylight; 4/5/6/7 Darkness (lit / unlit / no lighting / unknown) | C38: 1 — дневной свет; 0 — тьма
A39: CD — состояние дороги | B39: road_surface_conditions: 1 Dry; 2 Wet or damp; 3 Snow; 4 Frost or ice; 5 Flood | C39: 1 — сухое; 0 — иное (влажное, лёд, вода)
A40: t — номер квартала | B40: date | C40: t = (год − 2009)·4 + квартал, t = 1…36
A41: K1…K4 — квартал года | B41: date | C41: фиктивные переменные; K1 — эталонный уровень (K1 = 0)
A43: Обработка: Python 3 + pandas, чтение CSV с usecols, порциями по 500 тыс. строк; в книгу перенесены только 172 отобранных ДТП (лист ДТП_Корнуолл).
A44: Квартальные суммы (лист Таблица_наблюдений) считаются в Excel формулами СЧЁТЕСЛИМН/СУММЕСЛИМН по листу ДТП_Корнуолл.

Sheet ДТП_Корнуолл
A1: Отобранные ДТП: Корнуолл, сельская местность, со смертельным исходом, 2009–2017 (172 записи)
A2: Синие столбцы P–R — кодирование факторов формулами; S — признак попадания в выборку ВКР (170 ДТП)
A4: № | B4: collision_index | C4: Дата | D4: Время | E4: Год | F4: Кв. года | G4: t (1…36) | H4: Класс дороги | I4: day_of_week | J4: День недели | K4: light_conditions | L4: Освещённость | M4: road_surface | N4: Покрытие | O4: Пострадавших | P4: Pr (пт–вс) | Q4: Cv (свет) | R4: CD (сухо) | S4: В выборке ВКР
A5: 1 | B5: 200950GC2H002 | C5: 39830 | D5: 01:56 | E5: =YEAR(C5) -> 2009 | F5: =ROUNDUP(MONTH(C5)/3,0) -> 1 | G5: =(E5-2009)*4+F5 -> 1 | H5: A | I5: 7 | J5: сб | K5: 6 | L5: Тьма, без освещения | M5: 2 | N5: Влажное | O5: 1 | P5: =IF(OR(I5=1,I5=6,I5=7),1,0) -> 1 | Q5: =IF(K5=1,1,0) -> 0 | R5: =IF(M5=1,1,0) -> 0 | S5: 0
A6: 2 | B6: 200950BB2B001 | C6: 39839 | D6: 21:30 | E6: =YEAR(C6) -> 2009 | F6: =ROUNDUP(MONTH(C6)/3,0) -> 1 | G6: =(E6-2009)*4+F6 -> 1 | H6: B | I6: 2 | J6: пн | K6: 6 | L6: Тьма, без освещения | M6: 2 | N6: Влажное | O6: 1 | P6: =IF(OR(I6=1,I6=6,I6=7),1,0) -> 0 | Q6: =IF(K6=1,1,0) -> 0 | R6: =IF(M6=1,1,0) -> 0 | S6: 0
A7: 3 | B7: 200950AY2D003 | C7: 39865 | D7: 10:12 | E7: =YEAR(C7) -> 2009 | F7: =ROUNDUP(MONTH(C7)/3,0) -> 1 | G7: =(E7-2009)*4+F7 -> 1 | H7: B | I7: 7 | J7: сб | K7: 1 | L7: Дневной свет | M7: 1 | N7: Сухое | O7: 1 | P7: =IF(OR(I7=1,I7=6,I7=7),1,0) -> 1 | Q7: =IF(K7=1,1,0) -> 1 | R7: =IF(M7=1,1,0) -> 1 | S7: 1
A8: 4 | B8: 200950GP2I001 | C8: 39904 | D8: 08:31 | E8: =YEAR(C8) -> 2009 | F8: =ROUNDUP(MONTH(C8)/3,0) -> 2 | G8: =(E8-2009)*4+F8 -> 2 | H8: C | I8: 4 | J8: ср | K8: 1 | L8: Дневной свет | M8: 1 | N8: Сухое | O8: 1 | P8: =IF(OR(I8=1,I8=6,I8=7),1,0) -> 0 | Q8: =IF(K8=1,1,0) -> 1 | R8: =IF(M8=1,1,0) -> 1 | S8: 1
A9: 5 | B9: 200950BS2A012 | C9: 39914 | D9: 03:05 | E9: =YEAR(C9) -> 2009 | F9: =ROUNDUP(MONTH(C9)/3,0) -> 2 | G9: =(E9-2009)*4+F9 -> 2 | H9: A | I9: 7 | J9: сб | K9: 6 | L9: Тьма, без освещения | M9: 1 | N9: Сухое | O9: 1 | P9: =IF(OR(I9=1,I9=6,I9=7),1,0) -> 1 | Q9: =IF(K9=1,1,0) -> 0 | R9: =IF(M9=1,1,0) -> 1 | S9: 1
A10: 6 | B10: 200950BS2A013 | C10: 39918 | D10: 07:47 | E10: =YEAR(C10) -> 2009 | F10: =ROUNDUP(MONTH(C10)/3,0) -> 2 | G10: =(E10-2009)*4+F10 -> 2 | H10: A | I10: 4 | J10: ср | K10: 1 | L10: Дневной свет | M10: 2 | N10: Влажное | O10: 2 | P10: =IF(OR(I10=1,I10=6,I10=7),1,0) -> 0 | Q10: =IF(K10=1,1,0) -> 1 | R10: =IF(M10=1,1,0) -> 0 | S10: 1
A11: 7 | B11: 200950GA2D011 | C11: 39949 | D11: 19:19 | E11: =YEAR(C11) -> 2009 | F11: =ROUNDUP(MONTH(C11)/3,0) -> 2 | G11: =(E11-2009)*4+F11 -> 2 | H11: A | I11: 7 | J11: сб | K11: 1 | L11: Дневной свет | M11: 1 | N11: Сухое | O11: 1 | P11: =IF(OR(I11=1,I11=6,I11=7),1,0) -> 1 | Q11: =IF(K11=1,1,0) -> 1 | R11: =IF(M11=1,1,0) -> 1 | S11: 1
A12: 8 | B12: 200950BL2L006 | C12: 39977 | D12: 11:46 | E12: =YEAR(C12) -> 2009 | F12: =ROUNDUP(MONTH(C12)/3,0) -> 2 | G12: =(E12-2009)*4+F12 -> 2 | H12: A | I12: 7 | J12: сб | K12: 1 | L12: Дневной свет | M12: 1 | N12: Сухое | O12: 2 | P12: =IF(OR(I12=1,I12=6,I12=7),1,0) -> 1 | Q12: =IF(K12=1,1,0) -> 1 | R12: =IF(M12=1,1,0) -> 1 | S12: 1
A13: 9 | B13: 200950AH2E013 | C13: 39981 | D13: 14:53 | E13: =YEAR(C13) -> 2009 | F13: =ROUNDUP(MONTH(C13)/3,0) -> 2 | G13: =(E13-2009)*4+F13 -> 2 | H13: B | I13: 4 | J13: ср | K13: 1 | L13: Дневной свет | M13: 2 | N13: Влажное | O13: 3 | P13: =IF(OR(I13=1,I13=6,I13=7),1,0) -> 0 | Q13: =IF(K13=1,1,0) -> 1 | R13: =IF(M13=1,1,0) -> 0 | S13: 1
A14: 10 | B14: 200950GC2J007 | C14: 39981 | D14: 22:24 | E14: =YEAR(C14) -> 2009 | F14: =ROUNDUP(MONTH(C14)/3,0) -> 2 | G14: =(E14-2009)*4+F14 -> 2 | H14: B | I14: 4 | J14: ср | K14: 6 | L14: Тьма, без освещения | M14: 1 | N14: Сухое | O14: 4 | P14: =IF(OR(I14=1,I14=6,I14=7),1,0) -> 0 | Q14: =IF(K14=1,1,0) -> 0 | R14: =IF(M14=1,1,0) -> 1 | S14: 1
A15: 11 | B15: 200950BT2B001 | C15: 39993 | D15: 17:30 | E15: =YEAR(C15) -> 2009 | F15: =ROUNDUP(MONTH(C15)/3,0) -> 2 | G15: =(E15-2009)*4+F15 -> 2 | H15: B | I15: 2 | J15: пн | K15: 1 | L15: Дневной свет | M15: 1 | N15: Сухое | O15: 3 | P15: =IF(OR(I15=1,I15=6,I15=7),1,0) -> 0 | Q15: =IF(K15=1,1,0) -> 1 | R15: =IF(M15=1,1,0) -> 1 | S15: 1
A16: 12 | B16: 200950BE2C001 | C16: 39994 | D16: 23:00 | E16: =YEAR(C16) -> 2009 | F16: =ROUNDUP(MONTH(C16)/3,0) -> 2 | G16: =(E16-2009)*4+F16 -> 2 | H16: C | I16: 3 | J16: вт | K16: 6 | L16: Тьма, без освещения | M16: 1 | N16: Сухое | O16: 1 | P16: =IF(OR(I16=1,I16=6,I16=7),1,0) -> 0 | Q16: =IF(K16=1,1,0) -> 0 | R16: =IF(M16=1,1,0) -> 1 | S16: 1
... A176: 172 | B176: 2017500252666 | C176: 43087 | D176: 23:50 | E176: =YEAR(C176) -> 2017 | F176: =ROUNDUP(MONTH(C176)/3,0) -> 4 | G176: =(E176-2009)*4+F176 -> 36 | H176: A | I176: 2 | J176: пн | K176: 6 | L176: Тьма, без освещения | M176: 2 | N176: Влажное | O176: 2 | P176: =IF(OR(I176=1,I176=6,I176=7),1,0) -> 0 | Q176: =IF(K176=1,1,0) -> 0 | R176: =IF(M176=1,1,0) -> 0 | S176: 1
N177: Итого: | O177: =SUM(O5:O176) -> 426 | P177: =SUM(P5:P176) -> 88 | Q177: =SUM(Q5:Q176) -> 101 | R177: =SUM(R5:R176) -> 99 | S177: =SUM(S5:S176) -> 170

Sheet Таблица_наблюдений
A1: Таблица наблюдений по кварталам (аналог рис. 2.7 ВКР)
A4: t | B4: Год | C4: Кв. | D4: Y | E4: Pr | F4: Cv | G4: CD | H4: K1 | I4: K2 | J4: K3 | K4: K4 | L4: Y (ВКР) | M4: Pr (ВКР) | N4: Cv (ВКР) | O4: CD (ВКР) | P4: ΔY | Q4: ΔPr | R4: ΔCv | S4: ΔCD | T4: Y (172) | U4: Pr (172) | V4: Cv (172) | W4: CD (172)
A5: 1 | B5: =2009+INT((A5-1)/4) -> 2009 | C5: =MOD(A5-1,4)+1 -> 1 | D5: =COUNTIFS(ДТП_Корнуолл!$G$5:$G$176,A5,ДТП_Корнуолл!$S$5:$S$176,1) -> 1 | E5: =SUMIFS(ДТП_Корнуолл!$P$5:$P$176,ДТП_Корнуолл!$G$5:$G$176,A5,ДТП_Корнуолл!$S$5:$S$176,1) -> 1 | F5: =SUMIFS(ДТП_Корнуолл!$Q$5:$Q$176,ДТП_Корнуолл!$G$5:$G$176,A5,ДТП_Корнуолл!$S$5:$S$176,1) -> 1 | G5: =SUMIFS(ДТП_Корнуолл!$R$5:$R$176,ДТП_Корнуолл!$G$5:$G$176,A5,ДТП_Корнуолл!$S$5:$S$176,1) -> 1 | H5: =IF(C5=1,1,0) -> 1 | I5: =IF(C5=2,1,0) -> 0 | J5: =IF(C5=3,1,0) -> 0 | K5: =IF(C5=4,1,0) -> 0 | L5: 1 | M5: 1 | N5: 1 | O5: 1 | P5: =D5-L5 -> 0 | Q5: =E5-M5 -> 0 | R5: =F5-N5 -> 0 | S5: =G5-O5 -> 0 | T5: =COUNTIFS(ДТП_Корнуолл!$G$5:$G$176,A5) -> 3 | U5: =SUMIFS(ДТП_Корнуолл!$P$5:$P$176,ДТП_Корнуолл!$G$5:$G$176,A5) -> 2 | V5: =SUMIFS(ДТП_Корнуолл!$Q$5:$Q$176,ДТП_Корнуолл!$G$5:$G$176,A5) -> 1 | W5: =SUMIFS(ДТП_Корнуолл!$R$5:$R$176,ДТП_Корнуолл!$G$5:$G$176,A5) -> 1
A6: 2 | B6: =2009+INT((A6-1)/4) -> 2009 | C6: =MOD(A6-1,4)+1 -> 2 | D6: =COUNTIFS(ДТП_Корнуолл!$G$5:$G$176,A6,ДТП_Корнуолл!$S$5:$S$176,1) -> 9 | E6: =SUMIFS(ДТП_Корнуолл!$P$5:$P$176,ДТП_Корнуолл!$G$5:$G$176,A6,ДТП_Корнуолл!$S$5:$S$176,1) -> 3 | F6: =SUMIFS(ДТП_Корнуолл!$Q$5:$Q$176,ДТП_Корнуолл!$G$5:$G$176,A6,ДТП_Корнуолл!$S$5:$S$176,1) -> 6 | G6: =SUMIFS(ДТП_Корнуолл!$R$5:$R$176,ДТП_Корнуолл!$G$5:$G$176,A6,ДТП_Корнуолл!$S$5:$S$176,1) -> 7 | H6: =IF(C6=1,1,0) -> 0 | I6: =IF(C6=2,1,0) -> 1 | J6: =IF(C6=3,1,0) -> 0 | K6: =IF(C6=4,1,0) -> 0 | L6: 7 | M6: 3 | N6: 6 | O6: 7 | P6: =D6-L6 -> 2 | Q6: =E6-M6 -> 0 | R6: =F6-N6 -> 0 | S6: =G6-O6 -> 0 | T6: =COUNTIFS(ДТП_Корнуолл!$G$5:$G$176,A6) -> 9 | U6: =SUMIFS(ДТП_Корнуолл!$P$5:$P$176,ДТП_Корнуолл!$G$5:$G$176,A6) -> 3 | V6: =SUMIFS(ДТП_Корнуолл!$Q$5:$Q$176,ДТП_Корнуолл!$G$5:$G$176,A6) -> 6 | W6: =SUMIFS(ДТП_Корнуолл!$R$5:$R$176,ДТП_Корнуолл!$G$5:$G$176,A6) -> 7
A7: 3 | B7: =2009+INT((A7-1)/4) -> 2009 | C7: =MOD(A7-1,4)+1 -> 3 | D7: =COUNTIFS(ДТП_Корнуолл!$G$5:$G$176,A7,ДТП_Корнуолл!$S$5:$S$176,1) -> 3 | E7: =SUMIFS(ДТП_Корнуолл!$P$5:$P$176,ДТП_Корнуолл!$G$5:$G$176,A7,ДТП_Корнуолл!$S$5:$S$176,1) -> 2 | F7: =SUMIFS(ДТП_Корнуолл!$Q$5:$Q$176,ДТП_Корнуолл!$G$5:$G$176,A7,ДТП_Корнуолл!$S$5:$S$176,1) -> 2 | G7: =SUMIFS(ДТП_Корнуолл!$R$5:$R$176,ДТП_Корнуолл!$G$5:$G$176,A7,ДТП_Корнуолл!$S$5:$S$176,1) -> 3 | H7: =IF(C7=1,1,0) -> 0 | I7: =IF(C7=2,1,0) -> 0 | J7: =IF(C7=3,1,0) -> 1 | K7: =IF(C7=4,1,0) -> 0 | L7: 3 | M7: 2 | N7: 2 | O7: 3 | P7: =D7-L7 -> 0 | Q7: =E7-M7 -> 0 | R7: =F7-N7 -> 0 | S7: =G7-O7 -> 0 | T7: =COUNTIFS(ДТП_Корнуолл!$G$5:$G$176,A7) -> 3 | U7: =SUMIFS(ДТП_Корнуолл!$P$5:$P$176,ДТП_Корнуолл!$G$5:$G$176,A7) -> 2 | V7: =SUMIFS(ДТП_Корнуолл!$Q$5:$Q$176,ДТП_Корнуолл!$G$5:$G$176,A7) -> 2 | W7: =SUMIFS(ДТП_Корнуолл!$R$5:$R$176,ДТП_Корнуолл!$G$5:$G$176,A7) -> 3
A8: 4 | B8: =2009+INT((A8-1)/4) -> 2009 | C8: =MOD(A8-1,4)+1 -> 4 | D8: =COUNTIFS(ДТП_Корнуолл!$G$5:$G$176,A8,ДТП_Корнуолл!$S$5:$S$176,1) -> 7 | E8: =SUMIFS(ДТП_Корнуолл!$P$5:$P$176,ДТП_Корнуолл!$G$5:$G$176,A8,ДТП_Корнуолл!$S$5:$S$176,1) -> 3 | F8: =SUMIFS(ДТП_Корнуолл!$Q$5:$Q$176,ДТП_Корнуолл!$G$5:$G$176,A8,ДТП_Корнуолл!$S$5:$S$176,1) -> 1 | G8: =SUMIFS(ДТП_Корнуолл!$R$5:$R$176,ДТП_Корнуолл!$G$5:$G$176,A8,ДТП_Корнуолл!$S$5:$S$176,1) -> 2 | H8: =IF(C8=1,1,0) -> 0 | I8: =IF(C8=2,1,0) -> 0 | J8: =IF(C8=3,1,0) -> 0 | K8: =IF(C8=4,1,0) -> 1 | L8: 5 | M8: 3 | N8: 1 | O8: 2 | P8: =D8-L8 -> 2 | Q8: =E8-M8 -> 0 | R8: =F8-N8 -> 0 | S8: =G8-O8 -> 0 | T8: =COUNTIFS(ДТП_Корнуолл!$G$5:$G$176,A8) -> 7 | U8: =SUMIFS(ДТП_Корнуолл!$P$5:$P$176,ДТП_Корнуолл!$G$5:$G$176,A8) -> 3 | V8: =SUMIFS(ДТП_Корнуолл!$Q$5:$Q$176,ДТП_Корнуолл!$G$5:$G$176,A8) -> 1 | W8: =SUMIFS(ДТП_Корнуолл!$R$5:$R$176,ДТП_Корнуолл!$G$5:$G$176,A8) -> 2
A9: 5 | B9: =2009+INT((A9-1)/4) -> 2010 | C9: =MOD(A9-1,4)+1 -> 1 | D9: =COUNTIFS(ДТП_Корнуолл!$G$5:$G$176,A9,ДТП_Корнуолл!$S$5:$S$176,1) -> 7 | E9: =SUMIFS(ДТП_Корнуолл!$P$5:$P$176,ДТП_Корнуолл!$G$5:$G$176,A9,ДТП_Корнуолл!$S$5:$S$176,1) -> 2 | F9: =SUMIFS(ДТП_Корнуолл!$Q$5:$Q$176,ДТП_Корнуолл!$G$5:$G$176,A9,ДТП_Корнуолл!$S$5:$S$176,1) -> 4 | G9: =SUMIFS(ДТП_Корнуолл!$R$5:$R$176,ДТП_Корнуолл!$G$5:$G$176,A9,ДТП_Корнуолл!$S$5:$S$176,1) -> 3 | H9: =IF(C9=1,1,0) -> 1 | I9: =IF(C9=2,1,0) -> 0 | J9: =IF(C9=3,1,0) -> 0 | K9: =IF(C9=4,1,0) -> 0 | L9: 5 | M9: 2 | N9: 4 | O9: 3 | P9: =D9-L9 -> 2 | Q9: =E9-M9 -> 0 | R9: =F9-N9 -> 0 | S9: =G9-O9 -> 0 | T9: =COUNTIFS(ДТП_Корнуолл!$G$5:$G$176,A9) -> 7 | U9: =SUMIFS(ДТП_Корнуолл!$P$5:$P$176,ДТП_Корнуолл!$G$5:$G$176,A9) -> 2 | V9: =SUMIFS(ДТП_Корнуолл!$Q$5:$Q$176,ДТП_Корнуолл!$G$5:$G$176,A9) -> 4 | W9: =SUMIFS(ДТП_Корнуолл!$R$5:$R$176,ДТП_Корнуолл!$G$5:$G$176,A9) -> 3
A10: 6 | B10: =2009+INT((A10-1)/4) -> 2010 | C10: =MOD(A10-1,4)+1 -> 2 | D10: =COUNTIFS(ДТП_Корнуолл!$G$5:$G$176,A10,ДТП_Корнуолл!$S$5:$S$176,1) -> 8 | E10: =SUMIFS(ДТП_Корнуолл!$P$5:$P$176,ДТП_Корнуолл!$G$5:$G$176,A10,ДТП_Корнуолл!$S$5:$S$176,1) -> 2 | F10: =SUMIFS(ДТП_Корнуолл!$Q$5:$Q$176,ДТП_Корнуолл!$G$5:$G$176,A10,ДТП_Корнуолл!$S$5:$S$176,1) -> 7 | G10: =SUMIFS(ДТП_Корнуолл!$R$5:$R$176,ДТП_Корнуолл!$G$5:$G$176,A10,ДТП_Корнуолл!$S$5:$S$176,1) -> 7 | H10: =IF(C10=1,1,0) -> 0 | I10: =IF(C10=2,1,0) -> 1 | J10: =IF(C10=3,1,0) -> 0 | K10: =IF(C10=4,1,0) -> 0 | L10: 8 | M10: 2 | N10: 7 | O10: 7 | P10: =D10-L10 -> 0 | Q10: =E10-M10 -> 0 | R10: =F10-N10 -> 0 | S10: =G10-O10 -> 0 | T10: =COUNTIFS(ДТП_Корнуолл!$G$5:$G$176,A10) -> 8 | U10: =SUMIFS(ДТП_Корнуолл!$P$5:$P$176,ДТП_Корнуолл!$G$5:$G$176,A10) -> 2 | V10: =SUMIFS(ДТП_Корнуолл!$Q$5:$Q$176,ДТП_Корнуолл!$G$5:$G$176,A10) -> 7 | W10: =SUMIFS(ДТП_Корнуолл!$R$5:$R$176,ДТП_Корнуолл!$G$5:$G$176,A10) -> 7
A11: 7 | B11: =2009+INT((A11-1)/4) -> 2010 | C11: =MOD(A11-1,4)+1 -> 3 | D11: =COUNTIFS(ДТП_Корнуолл!$G$5:$G$176,A11,ДТП_Корнуолл!$S$5:$S$176,1) -> 0 | E11: =SUMIFS(ДТП_Корнуолл!$P$5:$P$176,ДТП_Корнуолл!$G$5:$G$176,A11,ДТП_Корнуолл!$S$5:$S$176,1) -> 0 | F11: =SUMIFS(ДТП_Корнуолл!$Q$5:$Q$176,ДТП_Корнуолл!$G$5:$G$176,A11,ДТП_Корнуолл!$S$5:$S$176,1) -> 0 | G11: =SUMIFS(ДТП_Корнуолл!$R$5:$R$176,ДТП_Корнуолл!$G$5:$G$176,A11,ДТП_Корнуолл!$S$5:$S$176,1) -> 0 | H11: =IF(C11=1,1,0) -> 0 | I11: =IF(C11=2,1,0) -> 0 | J11: =IF(C11=3,1,0) -> 1 | K11: =IF(C11=4,1,0) -> 0 | L11: 0 | M11: 0 | N11: 0 | O11: 0 | P11: =D11-L11 -> 0 | Q11: =E11-M11 -> 0 | R11: =F11-N11 -> 0 | S11: =G11-O11 -> 0 | T11: =COUNTIFS(ДТП_Корнуолл!$G$5:$G$176,A11) -> 0 | U11: =SUMIFS(ДТП_Корнуолл!$P$5:$P$176,ДТП_Корнуолл!$G$5:$G$176,A11) -> 0 | V11: =SUMIFS(ДТП_Корнуолл!$Q$5:$Q$176,ДТП_Корнуолл!$G$5:$G$176,A11) -> 0 | W11: =SUMIFS(ДТП_Корнуолл!$R$5:$R$176,ДТП_Корнуолл!$G$5:$G$176,A11) -> 0
A12: 8 | B12: =2009+INT((A12-1)/4) -> 2010 | C12: =MOD(A12-1,4)+1 -> 4 | D12: =COUNTIFS(ДТП_Корнуолл!$G$5:$G$176,A12,ДТП_Корнуолл!$S$5:$S$176,1) -> 6 | E12: =SUMIFS(ДТП_Корнуолл!$P$5:$P$176,ДТП_Корнуолл!$G$5:$G$176,A12,ДТП_Корнуолл!$S$5:$S$176,1) -> 4 | F12: =SUMIFS(ДТП_Корнуолл!$Q$5:$Q$176,ДТП_Корнуолл!$G$5:$G$176,A12,ДТП_Корнуолл!$S$5:$S$176,1) -> 1 | G12: =SUMIFS(ДТП_Корнуолл!$R$5:$R$176,ДТП_Корнуолл!$G$5:$G$176,A12,ДТП_Корнуолл!$S$5:$S$176,1) -> 0 | H12: =IF(C12=1,1,0) -> 0 | I12: =IF(C12=2,1,0) -> 0 | J12: =IF(C12=3,1,0) -> 0 | K12: =IF(C12=4,1,0) -> 1 | L12: 6 | M12: 4 | N12: 1 | O12: 0 | P12: =D12-L12 -> 0 | Q12: =E12-M12 -> 0 | R12: =F12-N12 -> 0 | S12: =G12-O12 -> 0 | T12: =COUNTIFS(ДТП_Корнуолл!$G$5:$G$176,A12) -> 6 | U12: =SUMIFS(ДТП_Корнуолл!$P$5:$P$176,ДТП_Корнуолл!$G$5:$G$176,A12) -> 4 | V12: =SUMIFS(ДТП_Корнуолл!$Q$5:$Q$176,ДТП_Корнуолл!$G$5:$G$176,A12) -> 1 | W12: =SUMIFS(ДТП_Корнуолл!$R$5:$R$176,ДТП_Корнуолл!$G$5:$G$176,A12) -> 0
A13: 9 | B13: =2009+INT((A13-1)/4) -> 2011 | C13: =MOD(A13-1,4)+1 -> 1 | D13: =COUNTIFS(ДТП_Корнуолл!$G$5:$G$176,A13,ДТП_Корнуолл!$S$5:$S$176,1) -> 2 | E13: =SUMIFS(ДТП_Корнуолл!$P$5:$P$176,ДТП_Корнуолл!$G$5:$G$176,A13,ДТП_Корнуолл!$S$5:$S$176,1) -> 1 | F13: =SUMIFS(ДТП_Корнуолл!$Q$5:$Q$176,ДТП_Корнуолл!$G$5:$G$176,A13,ДТП_Корнуолл!$S$5:$S$176,1) -> 1 | G13: =SUMIFS(ДТП_Корнуолл!$R$5:$R$176,ДТП_Корнуолл!$G$5:$G$176,A13,ДТП_Корнуолл!$S$5:$S$176,1) -> 0 | H13: =IF(C13=1,1,0) -> 1 | I13: =IF(C13=2,1,0) -> 0 | J13: =IF(C13=3,1,0) -> 0 | K13: =IF(C13=4,1,0) -> 0 | L13: 2 | M13: 1 | N13: 1 | O13: 0 | P13: =D13-L13 -> 0 | Q13: =E13-M13 -> 0 | R13: =F13-N13 -> 0 | S13: =G13-O13 -> 0 | T13: =COUNTIFS(ДТП_Корнуолл!$G$5:$G$176,A13) -> 2 | U13: =SUMIFS(ДТП_Корнуолл!$P$5:$P$176,ДТП_Корнуолл!$G$5:$G$176,A13) -> 1 | V13: =SUMIFS(ДТП_Корнуолл!$Q$5:$Q$176,ДТП_Корнуолл!$G$5:$G$176,A13) -> 1 | W13: =SUMIFS(ДТП_Корнуолл!$R$5:$R$176,ДТП_Корнуолл!$G$5:$G$176,A13) -> 0
A14: 10 | B14: =2009+INT((A14-1)/4) -> 2011 | C14: =MOD(A14-1,4)+1 -> 2 | D14: =COUNTIFS(ДТП_Корнуолл!$G$5:$G$176,A14,ДТП_Корнуолл!$S$5:$S$176,1) -> 5 | E14: =SUMIFS(ДТП_Корнуолл!$P$5:$P$176,ДТП_Корнуолл!$G$5:$G$176,A14,ДТП_Корнуолл!$S$5:$S$176,1) -> 2 | F14: =SUMIFS(ДТП_Корнуолл!$Q$5:$Q$176,ДТП_Корнуолл!$G$5:$G$176,A14,ДТП_Корнуолл!$S$5:$S$176,1) -> 4 | G14: =SUMIFS(ДТП_Корнуолл!$R$5:$R$176,ДТП_Корнуолл!$G$5:$G$176,A14,ДТП_Корнуолл!$S$5:$S$176,1) -> 5 | H14: =IF(C14=1,1,0) -> 0 | I14: =IF(C14=2,1,0) -> 1 | J14: =IF(C14=3,1,0) -> 0 | K14: =IF(C14=4,1,0) -> 0 | L14: 5 | M14: 2 | N14: 4 | O14: 5 | P14: =D14-L14 -> 0 | Q14: =E14-M14 -> 0 | R14: =F14-N14 -> 0 | S14: =G14-O14 -> 0 | T14: =COUNTIFS(ДТП_Корнуолл!$G$5:$G$176,A14) -> 5 | U14: =SUMIFS(ДТП_Корнуолл!$P$5:$P$176,ДТП_Корнуолл!$G$5:$G$176,A14) -> 2 | V14: =SUMIFS(ДТП_Корнуолл!$Q$5:$Q$176,ДТП_Корнуолл!$G$5:$G$176,A14) -> 4 | W14: =SUMIFS(ДТП_Корнуолл!$R$5:$R$176,ДТП_Корнуолл!$G$5:$G$176,A14) -> 5
A15: 11 | B15: =2009+INT((A15-1)/4) -> 2011 | C15: =MOD(A15-1,4)+1 -> 3 | D15: =COUNTIFS(ДТП_Корнуолл!$G$5:$G$176,A15,ДТП_Корнуолл!$S$5:$S$176,1) -> 5 | E15: =SUMIFS(ДТП_Корнуолл!$P$5:$P$176,ДТП_Корнуолл!$G$5:$G$176,A15,ДТП_Корнуолл!$S$5:$S$176,1) -> 1 | F15: =SUMIFS(ДТП_Корнуолл!$Q$5:$Q$176,ДТП_Корнуолл!$G$5:$G$176,A15,ДТП_Корнуолл!$S$5:$S$176,1) -> 5 | G15: =SUMIFS(ДТП_Корнуолл!$R$5:$R$176,ДТП_Корнуолл!$G$5:$G$176,A15,ДТП_Корнуолл!$S$5:$S$176,1) -> 2 | H15: =IF(C15=1,1,0) -> 0 | I15: =IF(C15=2,1,0) -> 0 | J15: =IF(C15=3,1,0) -> 1 | K15: =IF(C15=4,1,0) -> 0 | L15: 4 | M15: 1 | N15: 5 | O15: 2 | P15: =D15-L15 -> 1 | Q15: =E15-M15 -> 0 | R15: =F15-N15 -> 0 | S15: =G15-O15 -> 0 | T15: =COUNTIFS(ДТП_Корнуолл!$G$5:$G$176,A15) -> 5 | U15: =SUMIFS(ДТП_Корнуолл!$P$5:$P$176,ДТП_Корнуолл!$G$5:$G$176,A15) -> 1 | V15: =SUMIFS(ДТП_Корнуолл!$Q$5:$Q$176,ДТП_Корнуолл!$G$5:$G$176,A15) -> 5 | W15: =SUMIFS(ДТП_Корнуолл!$R$5:$R$176,ДТП_Корнуолл!$G$5:$G$176,A15) -> 2
A16: 12 | B16: =2009+INT((A16-1)/4) -> 2011 | C16: =MOD(A16-1,4)+1 -> 4 | D16: =COUNTIFS(ДТП_Корнуолл!$G$5:$G$176,A16,ДТП_Корнуолл!$S$5:$S$176,1) -> 5 | E16: =SUMIFS(ДТП_Корнуолл!$P$5:$P$176,ДТП_Корнуолл!$G$5:$G$176,A16,ДТП_Корнуолл!$S$5:$S$176,1) -> 4 | F16: =SUMIFS(ДТП_Корнуолл!$Q$5:$Q$176,ДТП_Корнуолл!$G$5:$G$176,A16,ДТП_Корнуолл!$S$5:$S$176,1) -> 1 | G16: =SUMIFS(ДТП_Корнуолл!$R$5:$R$176,ДТП_Корнуолл!$G$5:$G$176,A16,ДТП_Корнуолл!$S$5:$S$176,1) -> 3 | H16: =IF(C16=1,1,0) -> 0 | I16: =IF(C16=2,1,0) -> 0 | J16: =IF(C16=3,1,0) -> 0 | K16: =IF(C16=4,1,0) -> 1 | L16: 5 | M16: 4 | N16: 1 | O16: 3 | P16: =D16-L16 -> 0 | Q16: =E16-M16 -> 0 | R16: =F16-N16 -> 0 | S16: =G16-O16 -> 0 | T16: =COUNTIFS(ДТП_Корнуолл!$G$5:$G$176,A16) -> 5 | U16: =SUMIFS(ДТП_Корнуолл!$P$5:$P$176,ДТП_Корнуолл!$G$5:$G$176,A16) -> 4 | V16: =SUMIFS(ДТП_Корнуолл!$Q$5:$Q$176,ДТП_Корнуолл!$G$5:$G$176,A16) -> 1 | W16: =SUMIFS(ДТП_Корнуолл!$R$5:$R$176,ДТП_Корнуолл!$G$5:$G$176,A16) -> 3
... A40: 36 | B40: =2009+INT((A40-1)/4) -> 2017 | C40: =MOD(A40-1,4)+1 -> 4 | D40: =COUNTIFS(ДТП_Корнуолл!$G$5:$G$176,A40,ДТП_Корнуолл!$S$5:$S$176,1) -> 6 | E40: =SUMIFS(ДТП_Корнуолл!$P$5:$P$176,ДТП_Корнуолл!$G$5:$G$176,A40,ДТП_Корнуолл!$S$5:$S$176,1) -> 3 | F40: =SUMIFS(ДТП_Корнуолл!$Q$5:$Q$176,ДТП_Корнуолл!$G$5:$G$176,A40,ДТП_Корнуолл!$S$5:$S$176,1) -> 1 | G40: =SUMIFS(ДТП_Корнуолл!$R$5:$R$176,ДТП_Корнуолл!$G$5:$G$176,A40,ДТП_Корнуолл!$S$5:$S$176,1) -> 2 | H40: =IF(C40=1,1,0) -> 0 | I40: =IF(C40=2,1,0) -> 0 | J40: =IF(C40=3,1,0) -> 0 | K40: =IF(C40=4,1,0) -> 1 | L40: 5 | M40: 3 | N40: 1 | O40: 2 | P40: =D40-L40 -> 1 | Q40: =E40-M40 -> 0 | R40: =F40-N40 -> 0 | S40: =G40-O40 -> 0 | T40: =COUNTIFS(ДТП_Корнуолл!$G$5:$G$176,A40) -> 6 | U40: =SUMIFS(ДТП_Корнуолл!$P$5:$P$176,ДТП_Корнуолл!$G$5:$G$176,A40) -> 3 | V40: =SUMIFS(ДТП_Корнуолл!$Q$5:$Q$176,ДТП_Корнуолл!$G$5:$G$176,A40) -> 1 | W40: =SUMIFS(ДТП_Корнуолл!$R$5:$R$176,ДТП_Корнуолл!$G$5:$G$176,A40) -> 2
C41: Σ | D41: =SUM(D5:D40) -> 170 | E41: =SUM(E5:E40) -> 87 | F41: =SUM(F5:F40) -> 101 | G41: =SUM(G5:G40) -> 99 | L41: =SUM(L5:L40) -> 162 | M41: =SUM(M5:M40) -> 90 | N41: =SUM(N5:N40) -> 101 | O41: =SUM(O5:O40) -> 100 | P41: =SUM(P5:P40) -> 8 | Q41: =SUM(Q5:Q40) -> -3 | R41: =SUM(R5:R40) -> 0 | S41: =SUM(S5:S40) -> -1 | ... W41: =SUM(W5:W40) -> 99

Sheet МНК_STATS19
A1: МНК-оценки модели (2.3) по данным STATS19 (выборка как в ВКР, 170 ДТП)
A2: Y(t) = A0 + A1·t + K1δ1 + K2δ2 + K3δ3 + K4δ4 + Pr·δPr + Cv·δCv + CD·δCD; K1 — эталон (= 0). 35 кварталов (III кв. 2010 г. без ДТП исключён, как у автора)
A4: № | B4: 1 | C4: t | D4: K2 | E4: K3 | F4: K4 | G4: Pr | H4: Cv | I4: CD | J4: Y | K4: Ŷ | L4: E = Y − Ŷ | M4: E² | O4: ЛИНЕЙН(Y; t…CD; ИСТИНА; ИСТИНА) — порядок коэффициентов обратный
A5: 1 | B5: 1 | C5: =Таблица_наблюдений!A5 -> 1 | D5: =Таблица_наблюдений!I5 -> 0 | E5: =Таблица_наблюдений!J5 -> 0 | F5: =Таблица_наблюдений!K5 -> 0 | G5: =Таблица_наблюдений!E5 -> 1 | H5: =Таблица_наблюдений!F5 -> 1 | I5: =Таблица_наблюдений!G5 -> 1 | J5: =Таблица_наблюдений!D5 -> 1 | K5: =$P$13+$Q$13*C5+$S$13*D5+$T$13*E5+$U$13*F5+$V$13*G5+$W$13*H5+$X$13*I5 -> 2.3689469 | L5: =J5-K5 -> -1.3689469 | M5: =L5^2 -> 1.8740156 | P5: CD | Q5: Cv | R5: Pr | S5: K4 | T5: K3 | U5: K2 | V5: A1 | W5: A0
A6: 2 | B6: 1 | C6: =Таблица_наблюдений!A6 -> 2 | D6: =Таблица_наблюдений!I6 -> 1 | E6: =Таблица_наблюдений!J6 -> 0 | F6: =Таблица_наблюдений!K6 -> 0 | G6: =Таблица_наблюдений!E6 -> 3 | H6: =Таблица_наблюдений!F6 -> 6 | I6: =Таблица_наблюдений!G6 -> 7 | J6: =Таблица_наблюдений!D6 -> 9 | K6: =$P$13+$Q$13*C6+$S$13*D6+$T$13*E6+$U$13*F6+$V$13*G6+$W$13*H6+$X$13*I6 -> 7.9585447 | L6: =J6-K6 -> 1.0414553 | M6: =L6^2 -> 1.0846291 | O6: коэффициент | P6: {=IFERROR(LINEST(J5:J39,C5:I39,TRUE,TRUE),"")} -> 0.51652938 | Q6: 0.35457986 | R6: 0.56828668 | S6: 1.2077379 | T6: -0.08563519 | U6: -0.41037256 | V6: -0.0086785356 | W6: 0.93822952
A7: 3 | B7: 1 | C7: =Таблица_наблюдений!A7 -> 3 | D7: =Таблица_наблюдений!I7 -> 0 | E7: =Таблица_наблюдений!J7 -> 1 | F7: =Таблица_наблюдений!K7 -> 0 | G7: =Таблица_наблюдений!E7 -> 2 | H7: =Таблица_наблюдений!F7 -> 2 | I7: =Таблица_наблюдений!G7 -> 3 | J7: =Таблица_наблюдений!D7 -> 3 | K7: =$P$13+$Q$13*C7+$S$13*D7+$T$13*E7+$U$13*F7+$V$13*G7+$W$13*H7+$X$13*I7 -> 4.2218799 | L7: =J7-K7 -> -1.2218799 | M7: =L7^2 -> 1.4929906 | O7: ст. ошибка | P7: 0.21925381 | Q7: 0.17606831 | R7: 0.20440452 | S7: 0.61142911 | T7: 0.65826387 | U7: 0.7619332 | V7: 0.020770178 | W7: 0.69024513
A8: 4 | B8: 1 | C8: =Таблица_наблюдений!A8 -> 4 | D8: =Таблица_наблюдений!I8 -> 0 | E8: =Таблица_наблюдений!J8 -> 0 | F8: =Таблица_наблюдений!K8 -> 1 | G8: =Таблица_наблюдений!E8 -> 3 | H8: =Таблица_наблюдений!F8 -> 1 | I8: =Таблица_наблюдений!G8 -> 2 | J8: =Таблица_наблюдений!D8 -> 7 | K8: =$P$13+$Q$13*C8+$S$13*D8+$T$13*E8+$U$13*F8+$V$13*G8+$W$13*H8+$X$13*I8 -> 5.203752 | L8: =J8-K8 -> 1.796248 | M8: =L8^2 -> 3.226507 | O8: R² | s | P8: 0.73587132 | Q8: 1.2205497
A9: 5 | B9: 1 | C9: =Таблица_наблюдений!A9 -> 5 | D9: =Таблица_наблюдений!I9 -> 0 | E9: =Таблица_наблюдений!J9 -> 0 | F9: =Таблица_наблюдений!K9 -> 0 | G9: =Таблица_наблюдений!E9 -> 2 | H9: =Таблица_наблюдений!F9 -> 4 | I9: =Таблица_наблюдений!G9 -> 3 | J9: =Таблица_наблюдений!D9 -> 7 | K9: =$P$13+$Q$13*C9+$S$13*D9+$T$13*E9+$U$13*F9+$V$13*G9+$W$13*H9+$X$13*I9 -> 4.9993178 | L9: =J9-K9 -> 2.0006822 | M9: =L9^2 -> 4.0027294 | O9: F | df | P9: 10.746129 | Q9: 27
A10: 6 | B10: 1 | C10: =Таблица_наблюдений!A10 -> 6 | D10: =Таблица_наблюдений!I10 -> 1 | E10: =Таблица_наблюдений!J10 -> 0 | F10: =Таблица_наблюдений!K10 -> 0 | G10: =Таблица_наблюдений!E10 -> 2 | H10: =Таблица_наблюдений!F10 -> 7 | I10: =Таблица_наблюдений!G10 -> 7 | J10: =Таблица_наблюдений!D10 -> 8 | K10: =$P$13+$Q$13*C10+$S$13*D10+$T$13*E10+$U$13*F10+$V$13*G10+$W$13*H10+$X$13*I10 -> 7.7101237 | L10: =J10-K10 -> 0.28987626 | M10: =L10^2 -> 0.084028246 | O10: SSR | SSE | P10: 112.06269 | Q10: 40.223024
A11: 7 | B11: 1 | C11: =Таблица_наблюдений!A12 -> 8 | D11: =Таблица_наблюдений!I12 -> 0 | E11: =Таблица_наблюдений!J12 -> 0 | F11: =Таблица_наблюдений!K12 -> 1 | G11: =Таблица_наблюдений!E12 -> 4 | H11: =Таблица_наблюдений!F12 -> 1 | I11: =Таблица_наблюдений!G12 -> 0 | J11: =Таблица_наблюдений!D12 -> 6 | K11: =$P$13+$Q$13*C11+$S$13*D11+$T$13*E11+$U$13*F11+$V$13*G11+$W$13*H11+$X$13*I11 -> 4.7042657 | L11: =J11-K11 -> 1.2957343 | M11: =L11^2 -> 1.6789273
A12: 8 | B12: 1 | C12: =Таблица_наблюдений!A13 -> 9 | D12: =Таблица_наблюдений!I13 -> 0 | E12: =Таблица_наблюдений!J13 -> 0 | F12: =Таблица_наблюдений!K13 -> 0 | G12: =Таблица_наблюдений!E13 -> 1 | H12: =Таблица_наблюдений!F13 -> 1 | I12: =Таблица_наблюдений!G13 -> 0 | J12: =Таблица_наблюдений!D13 -> 2 | K12: =$P$13+$Q$13*C12+$S$13*D12+$T$13*E12+$U$13*F12+$V$13*G12+$W$13*H12+$X$13*I12 -> 1.7829892 | L12: =J12-K12 -> 0.21701077 | M12: =L12^2 -> 0.047093672 | O12: Коэффициенты модели (2.3) | P12: A0 | Q12: A1 | R12: K1 | S12: K2 | T12: K3 | U12: K4 | V12: Pr | W12: Cv | X12: CD
A13: 9 | B13: 1 | C13: =Таблица_наблюдений!A14 -> 10 | D13: =Таблица_наблюдений!I14 -> 1 | E13: =Таблица_наблюдений!J14 -> 0 | F13: =Таблица_наблюдений!K14 -> 0 | G13: =Таблица_наблюдений!E14 -> 2 | H13: =Таблица_наблюдений!F14 -> 4 | I13: =Таблица_наблюдений!G14 -> 5 | J13: =Таблица_наблюдений!D14 -> 5 | K13: =$P$13+$Q$13*C13+$S$13*D13+$T$13*E13+$U$13*F13+$V$13*G13+$W$13*H13+$X$13*I13 -> 5.5786113 | L13: =J13-K13 -> -0.57861127 | M13: =L13^2 -> 0.334791 | O13: значение | P13: =W6 -> 0.93822952 | Q13: =V6 -> -0.0086785356 | R13: 0 | S13: =U6 -> -0.41037256 | T13: =T6 -> -0.08563519 | U13: =S6 -> 1.2077379 | V13: =R6 -> 0.56828668 | W13: =Q6 -> 0.35457986 | X13: =P6 -> 0.51652938
A14: 10 | B14: 1 | C14: =Таблица_наблюдений!A15 -> 11 | D14: =Таблица_наблюдений!I15 -> 0 | E14: =Таблица_наблюдений!J15 -> 1 | F14: =Таблица_наблюдений!K15 -> 0 | G14: =Таблица_наблюдений!E15 -> 1 | H14: =Таблица_наблюдений!F15 -> 5 | I14: =Таблица_наблюдений!G15 -> 2 | J14: =Таблица_наблюдений!D15 -> 5 | K14: =$P$13+$Q$13*C14+$S$13*D14+$T$13*E14+$U$13*F14+$V$13*G14+$W$13*H14+$X$13*I14 -> 4.1313752 | L14: =J14-K14 -> 0.86862484 | M14: =L14^2 -> 0.75450912 | O14: ст. ошибка | P14: =W7 -> 0.69024513 | Q14: =V7 -> 0.020770178 | R14: — | S14: =U7 -> 0.7619332 | T14: =T7 -> 0.65826387 | U14: =S7 -> 0.61142911 | V14: =R7 -> 0.20440452 | W14: =Q7 -> 0.17606831 | X14: =P7 -> 0.21925381
A15: 11 | B15: 1 | C15: =Таблица_наблюдений!A16 -> 12 | D15: =Таблица_наблюдений!I16 -> 0 | E15: =Таблица_наблюдений!J16 -> 0 | F15: =Таблица_наблюдений!K16 -> 1 | G15: =Таблица_наблюдений!E16 -> 4 | H15: =Таблица_наблюдений!F16 -> 1 | I15: =Таблица_наблюдений!G16 -> 3 | J15: =Таблица_наблюдений!D16 -> 5 | K15: =$P$13+$Q$13*C15+$S$13*D15+$T$13*E15+$U$13*F15+$V$13*G15+$W$13*H15+$X$13*I15 -> 6.2191397 | L15: =J15-K15 -> -1.2191397 | M15: =L15^2 -> 1.4863017 | O15: t-статистика | P15: =P13/P14 -> 1.35927 | Q15: =Q13/Q14 -> -0.41783637 | R15: — | S15: =S13/S14 -> -0.53859389 | T15: =T13/T14 -> -0.1300925 | U15: =U13/U14 -> 1.9752706 | V15: =V13/V14 -> 2.7802061 | W15: =W13/W14 -> 2.0138767 | X15: =X13/X14 -> 2.3558513
A16: 12 | B16: 1 | C16: =Таблица_наблюдений!A17 -> 13 | D16: =Таблица_наблюдений!I17 -> 0 | E16: =Таблица_наблюдений!J17 -> 0 | F16: =Таблица_наблюдений!K17 -> 0 | G16: =Таблица_наблюдений!E17 -> 4 | H16: =Таблица_наблюдений!F17 -> 2 | I16: =Таблица_наблюдений!G17 -> 2 | J16: =Таблица_наблюдений!D17 -> 4 | K16: =$P$13+$Q$13*C16+$S$13*D16+$T$13*E16+$U$13*F16+$V$13*G16+$W$13*H16+$X$13*I16 -> 4.8407737 | L16: =J16-K16 -> -0.84077374 | M16: =L16^2 -> 0.70690048 | O16: Критическое t (α = 0,05; df = 27): | W16: =_xlfn.T.INV.2T(0.05,27) -> 2.0518305
A17: 13 | B17: 1 | C17: =Таблица_наблюдений!A18 -> 14 | D17: =Таблица_наблюдений!I18 -> 1 | E17: =Таблица_наблюдений!J18 -> 0 | F17: =Таблица_наблюдений!K18 -> 0 | G17: =Таблица_наблюдений!E18 -> 2 | H17: =Таблица_наблюдений!F18 -> 4 | I17: =Таблица_наблюдений!G18 -> 3 | J17: =Таблица_наблюдений!D18 -> 4 | K17: =$P$13+$Q$13*C17+$S$13*D17+$T$13*E17+$U$13*F17+$V$13*G17+$W$13*H17+$X$13*I17 -> 4.5108384 | L17: =J17-K17 -> -0.51083838 | M17: =L17^2 -> 0.26095585
A18: 14 | B18: 1 | C18: =Таблица_наблюдений!A19 -> 15 | D18: =Таблица_наблюдений!I19 -> 0 | E18: =Таблица_наблюдений!J19 -> 1 | F18: =Таблица_наблюдений!K19 -> 0 | G18: =Таблица_наблюдений!E19 -> 2 | H18: =Таблица_наблюдений!F19 -> 4 | I18: =Таблица_наблюдений!G19 -> 4 | J18: =Таблица_наблюдений!D19 -> 6 | K18: =$P$13+$Q$13*C18+$S$13*D18+$T$13*E18+$U$13*F18+$V$13*G18+$W$13*H18+$X$13*I18 -> 5.3434266 | L18: =J18-K18 -> 0.65657341 | M18: =L18^2 -> 0.43108864 | O18: Проверка: решение нормальных уравнений b = (XᵀX)⁻¹·Xᵀy (МУМНОЖ, МОБР, ТРАНСП)
A19: 15 | B19: 1 | C19: =Таблица_наблюдений!A20 -> 16 | D19: =Таблица_наблюдений!I20 -> 0 | E19: =Таблица_наблюдений!J20 -> 0 | F19: =Таблица_наблюдений!K20 -> 1 | G19: =Таблица_наблюдений!E20 -> 5 | H19: =Таблица_наблюдений!F20 -> 5 | I19: =Таблица_наблюдений!G20 -> 2 | J19: =Таблица_наблюдений!D20 -> 7 | K19: =$P$13+$Q$13*C19+$S$13*D19+$T$13*E19+$U$13*F19+$V$13*G19+$W$13*H19+$X$13*I19 -> 7.6545023 | L19: =J19-K19 -> -0.65450232 | M19: =L19^2 -> 0.42837329 | O19: A0 | P19: {=MMULT(MINVERSE(MMULT(TRANSPOSE(B5:I39),B5:I39)),MMULT(TRANSPOSE(B5:I39),J5:J39))} -> 0.93822952
A20: 16 | B20: 1 | C20: =Таблица_наблюдений!A21 -> 17 | D20: =Таблица_наблюдений!I21 -> 0 | E20: =Таблица_наблюдений!J21 -> 0 | F20: =Таблица_наблюдений!K21 -> 0 | G20: =Таблица_наблюдений!E21 -> 4 | H20: =Таблица_наблюдений!F21 -> 4 | I20: =Таблица_наблюдений!G21 -> 4 | J20: =Таблица_наблюдений!D21 -> 5 | K20: =$P$13+$Q$13*C20+$S$13*D20+$T$13*E20+$U$13*F20+$V$13*G20+$W$13*H20+$X$13*I20 -> 6.5482781 | L20: =J20-K20 -> -1.5482781 | M20: =L20^2 -> 2.397165 | O20: A1 | P20: -0.0086785356
A21: 17 | B21: 1 | C21: =Таблица_наблюдений!A22 -> 18 | D21: =Таблица_наблюдений!I22 -> 1 | E21: =Таблица_наблюдений!J22 -> 0 | F21: =Таблица_наблюдений!K22 -> 0 | G21: =Таблица_наблюдений!E22 -> 2 | H21: =Таблица_наблюдений!F22 -> 2 | I21: =Таблица_наблюдений!G22 -> 3 | J21: =Таблица_наблюдений!D22 -> 3 | K21: =$P$13+$Q$13*C21+$S$13*D21+$T$13*E21+$U$13*F21+$V$13*G21+$W$13*H21+$X$13*I21 -> 3.7669645 | L21: =J21-K21 -> -0.76696452 | M21: =L21^2 -> 0.58823457 | O21: K2 | P21: -0.41037256
A22: 18 | B22: 1 | C22: =Таблица_наблюдений!A23 -> 19 | D22: =Таблица_наблюдений!I23 -> 0 | E22: =Таблица_наблюдений!J23 -> 1 | F22: =Таблица_наблюдений!K23 -> 0 | G22: =Таблица_наблюдений!E23 -> 2 | H22: =Таблица_наблюдений!F23 -> 3 | I22: =Таблица_наблюдений!G23 -> 2 | J22: =Таблица_наблюдений!D23 -> 4 | K22: =$P$13+$Q$13*C22+$S$13*D22+$T$13*E22+$U$13*F22+$V$13*G22+$W$13*H22+$X$13*I22 -> 3.9210738 | L22: =J22-K22 -> 0.078926164 | M22: =L22^2 -> 0.0062293394 | O22: K3 | P22: -0.08563519
A23: 19 | B23: 1 | C23: =Таблица_наблюдений!A24 -> 20 | D23: =Таблица_наблюдений!I24 -> 0 | E23: =Таблица_наблюдений!J24 -> 0 | F23: =Таблица_наблюдений!K24 -> 1 | G23: =Таблица_наблюдений!E24 -> 3 | H23: =Таблица_наблюдений!F24 -> 3 | I23: =Таблица_наблюдений!G24 -> 1 | J23: =Таблица_наблюдений!D24 -> 6 | K23: =$P$13+$Q$13*C23+$S$13*D23+$T$13*E23+$U$13*F23+$V$13*G23+$W$13*H23+$X$13*I23 -> 5.2575257 | L23: =J23-K23 -> 0.74247427 | M23: =L23^2 -> 0.55126805 | O23: K4 | P23: 1.2077379
A24: 20 | B24: 1 | C24: =Таблица_наблюдений!A25 -> 21 | D24: =Таблица_наблюдений!I25 -> 0 | E24: =Таблица_наблюдений!J25 -> 0 | F24: =Таблица_наблюдений!K25 -> 0 | G24: =Таблица_наблюдений!E25 -> 4 | H24: =Таблица_наблюдений!F25 -> 4 | I24: =Таблица_наблюдений!G25 -> 3 | J24: =Таблица_наблюдений!D25 -> 6 | K24: =$P$13+$Q$13*C24+$S$13*D24+$T$13*E24+$U$13*F24+$V$13*G24+$W$13*H24+$X$13*I24 -> 5.9970345 | L24: =J24-K24 -> 0.0029654531 | M24: =L24^2 -> 8.793912e-06 | O24: Pr | P24: 0.56828668
A25: 21 | B25: 1 | C25: =Таблица_наблюдений!A26 -> 22 | D25: =Таблица_наблюдений!I26 -> 1 | E25: =Таблица_наблюдений!J26 -> 0 | F25: =Таблица_наблюдений!K26 -> 0 | G25: =Таблица_наблюдений!E26 -> 3 | H25: =Таблица_наблюдений!F26 -> 6 | I25: =Таблица_наблюдений!G26 -> 6 | J25: =Таблица_наблюдений!D26 -> 7 | K25: =$P$13+$Q$13*C25+$S$13*D25+$T$13*E25+$U$13*F25+$V$13*G25+$W$13*H25+$X$13*I25 -> 7.2684446 | L25: =J25-K25 -> -0.26844462 | M25: =L25^2 -> 0.072062511 | O25: Cv | P25: 0.35457986
A26: 22 | B26: 1 | C26: =Таблица_наблюдений!A27 -> 23 | D26: =Таблица_наблюдений!I27 -> 0 | E26: =Таблица_наблюдений!J27 -> 1 | F26: =Таблица_наблюдений!K27 -> 0 | G26: =Таблица_наблюдений!E27 -> 3 | H26: =Таблица_наблюдений!F27 -> 6 | I26: =Таблица_наблюдений!G27 -> 5 | J26: =Таблица_наблюдений!D27 -> 7 | K26: =$P$13+$Q$13*C26+$S$13*D26+$T$13*E26+$U$13*F26+$V$13*G26+$W$13*H26+$X$13*I26 -> 7.0679741 | L26: =J26-K26 -> -0.067974075 | M26: =L26^2 -> 0.0046204749 | O26: CD | P26: 0.51652938
A27: 23 | B27: 1 | C27: =Таблица_наблюдений!A28 -> 24 | D27: =Таблица_наблюдений!I28 -> 0 | E27: =Таблица_наблюдений!J28 -> 0 | F27: =Таблица_наблюдений!K28 -> 1 | G27: =Таблица_наблюдений!E28 -> 3 | H27: =Таблица_наблюдений!F28 -> 3 | I27: =Таблица_наблюдений!G28 -> 2 | J27: =Таблица_наблюдений!D28 -> 3 | K27: =$P$13+$Q$13*C27+$S$13*D27+$T$13*E27+$U$13*F27+$V$13*G27+$W$13*H27+$X$13*I27 -> 5.739341 | L27: =J27-K27 -> -2.739341 | M27: =L27^2 -> 7.5039889
A28: 24 | B28: 1 | C28: =Таблица_наблюдений!A29 -> 25 | D28: =Таблица_наблюдений!I29 -> 0 | E28: =Таблица_наблюдений!J29 -> 0 | F28: =Таблица_наблюдений!K29 -> 0 | G28: =Таблица_наблюдений!E29 -> 1 | H28: =Таблица_наблюдений!F29 -> 1 | I28: =Таблица_наблюдений!G29 -> 0 | J28: =Таблица_наблюдений!D29 -> 1 | K28: =$P$13+$Q$13*C28+$S$13*D28+$T$13*E28+$U$13*F28+$V$13*G28+$W$13*H28+$X$13*I28 -> 1.6441327 | L28: =J28-K28 -> -0.64413266 | M28: =L28^2 -> 0.41490689 | O28: Качество модели
A29: 25 | B29: 1 | C29: =Таблица_наблюдений!A30 -> 26 | D29: =Таблица_наблюдений!I30 -> 1 | E29: =Таблица_наблюдений!J30 -> 0 | F29: =Таблица_наблюдений!K30 -> 0 | G29: =Таблица_наблюдений!E30 -> 0 | H29: =Таблица_наблюдений!F30 -> 1 | I29: =Таблица_наблюдений!G30 -> 1 | J29: =Таблица_наблюдений!D30 -> 1 | K29: =$P$13+$Q$13*C29+$S$13*D29+$T$13*E29+$U$13*F29+$V$13*G29+$W$13*H29+$X$13*I29 -> 1.1733243 | L29: =J29-K29 -> -0.17332426 | M29: =L29^2 -> 0.0300413 | O29: n (наблюдений) | P29: =COUNT(J5:J39) -> 35
A30: 26 | B30: 1 | C30: =Таблица_наблюдений!A31 -> 27 | D30: =Таблица_наблюдений!I31 -> 0 | E30: =Таблица_наблюдений!J31 -> 1 | F30: =Таблица_наблюдений!K31 -> 0 | G30: =Таблица_наблюдений!E31 -> 3 | H30: =Таблица_наблюдений!F31 -> 1 | I30: =Таблица_наблюдений!G31 -> 3 | J30: =Таблица_наблюдений!D31 -> 4 | K30: =$P$13+$Q$13*C30+$S$13*D30+$T$13*E30+$U$13*F30+$V$13*G30+$W$13*H30+$X$13*I30 -> 4.2273019 | L30: =J30-K30 -> -0.22730189 | M30: =L30^2 -> 0.05166615 | O30: k (параметров) | P30: 8
A31: 27 | B31: 1 | C31: =Таблица_наблюдений!A32 -> 28 | D31: =Таблица_наблюдений!I32 -> 0 | E31: =Таблица_наблюдений!J32 -> 0 | F31: =Таблица_наблюдений!K32 -> 1 | G31: =Таблица_наблюдений!E32 -> 1 | H31: =Таблица_наблюдений!F32 -> 0 | I31: =Таблица_наблюдений!G32 -> 1 | J31: =Таблица_наблюдений!D32 -> 2 | K31: =$P$13+$Q$13*C31+$S$13*D31+$T$13*E31+$U$13*F31+$V$13*G31+$W$13*H31+$X$13*I31 -> 2.9877845 | L31: =J31-K31 -> -0.98778451 | M31: =L31^2 -> 0.97571824 | O31: SSE = ΣE² | P31: =M40 -> 40.223024
A32: 28 | B32: 1 | C32: =Таблица_наблюдений!A33 -> 29 | D32: =Таблица_наблюдений!I33 -> 0 | E32: =Таблица_наблюдений!J33 -> 0 | F32: =Таблица_наблюдений!K33 -> 0 | G32: =Таблица_наблюдений!E33 -> 2 | H32: =Таблица_наблюдений!F33 -> 1 | I32: =Таблица_наблюдений!G33 -> 2 | J32: =Таблица_наблюдений!D33 -> 4 | K32: =$P$13+$Q$13*C32+$S$13*D32+$T$13*E32+$U$13*F32+$V$13*G32+$W$13*H32+$X$13*I32 -> 3.210764 | L32: =J32-K32 -> 0.78923604 | M32: =L32^2 -> 0.62289353 | O32: SST = ДИСП.Σ(Y) | P32: =DEVSQ(J5:J39) -> 152.28571
A33: 29 | B33: 1 | C33: =Таблица_наблюдений!A34 -> 30 | D33: =Таблица_наблюдений!I34 -> 1 | E33: =Таблица_наблюдений!J34 -> 0 | F33: =Таблица_наблюдений!K34 -> 0 | G33: =Таблица_наблюдений!E34 -> 1 | H33: =Таблица_наблюдений!F34 -> 4 | I33: =Таблица_наблюдений!G34 -> 3 | J33: =Таблица_наблюдений!D34 -> 4 | K33: =$P$13+$Q$13*C33+$S$13*D33+$T$13*E33+$U$13*F33+$V$13*G33+$W$13*H33+$X$13*I33 -> 3.8036951 | L33: =J33-K33 -> 0.19630487 | M33: =L33^2 -> 0.038535604 | O33: R² = 1 − SSE/SST | P33: =1-P31/P32 -> 0.73587132
A34: 30 | B34: 1 | C34: =Таблица_наблюдений!A35 -> 31 | D34: =Таблица_наблюдений!I35 -> 0 | E34: =Таблица_наблюдений!J35 -> 1 | F34: =Таблица_наблюдений!K35 -> 0 | G34: =Таблица_наблюдений!E35 -> 6 | H34: =Таблица_наблюдений!F35 -> 4 | I34: =Таблица_наблюдений!G35 -> 4 | J34: =Таблица_наблюдений!D35 -> 9 | K34: =$P$13+$Q$13*C34+$S$13*D34+$T$13*E34+$U$13*F34+$V$13*G34+$W$13*H34+$X$13*I34 -> 7.4777167 | L34: =J34-K34 -> 1.5222833 | M34: =L34^2 -> 2.3173463 | O34: R (множественный) | P34: =SQRT(P33) -> 0.85782942
A35: 31 | B35: 1 | C35: =Таблица_наблюдений!A36 -> 32 | D35: =Таблица_наблюдений!I36 -> 0 | E35: =Таблица_наблюдений!J36 -> 0 | F35: =Таблица_наблюдений!K36 -> 1 | G35: =Таблица_наблюдений!E36 -> 1 | H35: =Таблица_наблюдений!F36 -> 1 | I35: =Таблица_наблюдений!G36 -> 1 | J35: =Таблица_наблюдений!D36 -> 4 | K35: =$P$13+$Q$13*C35+$S$13*D35+$T$13*E35+$U$13*F35+$V$13*G35+$W$13*H35+$X$13*I35 -> 3.3076502 | L35: =J35-K35 -> 0.69234977 | M35: =L35^2 -> 0.47934821 | O35: F-статистика | P35: =(P32-P31)/(P30-1)/(P31/(P29-P30)) -> 10.746129
A36: 32 | B36: 1 | C36: =Таблица_наблюдений!A37 -> 33 | D36: =Таблица_наблюдений!I37 -> 0 | E36: =Таблица_наблюдений!J37 -> 0 | F36: =Таблица_наблюдений!K37 -> 0 | G36: =Таблица_наблюдений!E37 -> 1 | H36: =Таблица_наблюдений!F37 -> 1 | I36: =Таблица_наблюдений!G37 -> 2 | J36: =Таблица_наблюдений!D37 -> 4 | K36: =$P$13+$Q$13*C36+$S$13*D36+$T$13*E36+$U$13*F36+$V$13*G36+$W$13*H36+$X$13*I36 -> 2.6077631 | L36: =J36-K36 -> 1.3922369 | M36: =L36^2 -> 1.9383235 | O36: p-значение F | P36: =_xlfn.F.DIST.RT(P35,P30-1,P29-P30) -> 2.1088991e-06
A37: 33 | B37: 1 | C37: =Таблица_наблюдений!A38 -> 34 | D37: =Таблица_наблюдений!I38 -> 1 | E37: =Таблица_наблюдений!J38 -> 0 | F37: =Таблица_наблюдений!K38 -> 0 | G37: =Таблица_наблюдений!E38 -> 3 | H37: =Таблица_наблюдений!F38 -> 2 | I37: =Таблица_наблюдений!G38 -> 5 | J37: =Таблица_наблюдений!D38 -> 6 | K37: =$P$13+$Q$13*C37+$S$13*D37+$T$13*E37+$U$13*F37+$V$13*G37+$W$13*H37+$X$13*I37 -> 5.2294534 | L37: =J37-K37 -> 0.77054662 | M37: =L37^2 -> 0.59374209 | O37: СКО остатков s | P37: =SQRT(P31/(P29-P30)) -> 1.2205497
A38: 34 | B38: 1 | C38: =Таблица_наблюдений!A39 -> 35 | D38: =Таблица_наблюдений!I39 -> 0 | E38: =Таблица_наблюдений!J39 -> 1 | F38: =Таблица_наблюдений!K39 -> 0 | G38: =Таблица_наблюдений!E39 -> 3 | H38: =Таблица_наблюдений!F39 -> 5 | I38: =Таблица_наблюдений!G39 -> 5 | J38: =Таблица_наблюдений!D39 -> 5 | K38: =$P$13+$Q$13*C38+$S$13*D38+$T$13*E38+$U$13*F38+$V$13*G38+$W$13*H38+$X$13*I38 -> 6.6092518 | L38: =J38-K38 -> -1.6092518 | M38: =L38^2 -> 2.5896913 | O38: Среднее E² (как М37 у автора) | P38: =P31/P29 -> 1.1492293
A39: 35 | B39: 1 | C39: =Таблица_наблюдений!A40 -> 36 | D39: =Таблица_наблюдений!I40 -> 0 | E39: =Таблица_наблюдений!J40 -> 0 | F39: =Таблица_наблюдений!K40 -> 1 | G39: =Таблица_наблюдений!E40 -> 3 | H39: =Таблица_наблюдений!F40 -> 1 | I39: =Таблица_наблюдений!G40 -> 2 | J39: =Таблица_наблюдений!D40 -> 6 | K39: =$P$13+$Q$13*C39+$S$13*D39+$T$13*E39+$U$13*F39+$V$13*G39+$W$13*H39+$X$13*I39 -> 4.9260388 | L39: =J39-K39 -> 1.0739612 | M39: =L39^2 -> 1.1533926
I40: Σ | J40: =SUM(J5:J39) -> 170 | K40: =SUM(K5:K39) -> 170 | L40: =SUM(L5:L39) -> 3.2862602e-14 | M40: =SUM(M5:M39) -> 40.223024

Sheet МНК_ВКР
A1: Повтор МНК по таблице автора ВКР (рис. 3.2) — проверка его коэффициентов
A2: Исходные данные перенесены из рис. 3.2 ВКР без изменений. Автор решал задачу «Поиском решения» (ОПГ); здесь — ЛИНЕЙН и нормальные уравнения
A4: № | B4: 1 | C4: t | D4: K2 | E4: K3 | F4: K4 | G4: Pr | H4: Cv | I4: CD | J4: Y | K4: Ŷ | L4: E = Y − Ŷ | M4: E² | O4: ЛИНЕЙН(Y; t…CD; ИСТИНА; ИСТИНА) — порядок коэффициентов обратный
A5: 1 | B5: 1 | C5: 1 | D5: 0 | E5: 0 | F5: 0 | G5: 1 | H5: 1 | I5: 1 | J5: 1 | K5: =$P$13+$Q$13*C5+$S$13*D5+$T$13*E5+$U$13*F5+$V$13*G5+$W$13*H5+$X$13*I5 -> 2.0170624 | L5: =J5-K5 -> -1.0170624 | M5: =L5^2 -> 1.0344159 | P5: CD | Q5: Cv | R5: Pr | S5: K4 | T5: K3 | U5: K2 | V5: A1 | W5: A0
A6: 2 | B6: 1 | C6: 2 | D6: 1 | E6: 0 | F6: 0 | G6: 3 | H6: 6 | I6: 7 | J6: 7 | K6: =$P$13+$Q$13*C6+$S$13*D6+$T$13*E6+$U$13*F6+$V$13*G6+$W$13*H6+$X$13*I6 -> 7.1376731 | L6: =J6-K6 -> -0.13767306 | M6: =L6^2 -> 0.018953871 | O6: коэффициент | P6: {=IFERROR(LINEST(J5:J39,C5:I39,TRUE,TRUE),"")} -> 0.44186157 | Q6: 0.32504632 | R6: 0.55701626 | S6: 0.93609749 | T6: -0.033986403 | U6: -0.27773881 | V6: 0.007915906 | W6: 0.68522234
A7: 3 | B7: 1 | C7: 3 | D7: 0 | E7: 1 | F7: 0 | G7: 2 | H7: 2 | I7: 3 | J7: 3 | K7: =$P$13+$Q$13*C7+$S$13*D7+$T$13*E7+$U$13*F7+$V$13*G7+$W$13*H7+$X$13*I7 -> 3.7646935 | L7: =J7-K7 -> -0.76469354 | M7: =L7^2 -> 0.58475621 | O7: ст. ошибка | P7: 0.14965811 | Q7: 0.12190626 | R7: 0.13170847 | S7: 0.44123865 | T7: 0.46892259 | U7: 0.53744489 | V7: 0.014757941 | W7: 0.45863325
A8: 4 | B8: 1 | C8: 4 | D8: 0 | E8: 0 | F8: 1 | G8: 3 | H8: 1 | I8: 2 | J8: 5 | K8: =$P$13+$Q$13*C8+$S$13*D8+$T$13*E8+$U$13*F8+$V$13*G8+$W$13*H8+$X$13*I8 -> 4.5328017 | L8: =J8-K8 -> 0.4671983 | M8: =L8^2 -> 0.21827425 | O8: R² | s | P8: 0.84352246 | Q8: 0.86856427
A9: 5 | B9: 1 | C9: 5 | D9: 0 | E9: 0 | F9: 0 | G9: 2 | H9: 4 | I9: 3 | J9: 5 | K9: =$P$13+$Q$13*C9+$S$13*D9+$T$13*E9+$U$13*F9+$V$13*G9+$W$13*H9+$X$13*I9 -> 4.4646044 | L9: =J9-K9 -> 0.53539561 | M9: =L9^2 -> 0.28664845 | O9: F | df | P9: 20.792675 | Q9: 27
A10: 6 | B10: 1 | C10: 6 | D10: 1 | E10: 0 | F10: 0 | G10: 2 | H10: 7 | I10: 7 | J10: 8 | K10: =$P$13+$Q$13*C10+$S$13*D10+$T$13*E10+$U$13*F10+$V$13*G10+$W$13*H10+$X$13*I10 -> 6.9373667 | L10: =J10-K10 -> 1.0626333 | M10: =L10^2 -> 1.1291894 | O10: SSR | SSE | P10: 109.80252 | Q10: 20.368905
A11: 7 | B11: 1 | C11: 8 | D11: 0 | E11: 0 | F11: 1 | G11: 4 | H11: 1 | I11: 0 | J11: 6 | K11: =$P$13+$Q$13*C11+$S$13*D11+$T$13*E11+$U$13*F11+$V$13*G11+$W$13*H11+$X$13*I11 -> 4.2377584 | L11: =J11-K11 -> 1.7622416 | M11: =L11^2 -> 3.1054953
A12: 8 | B12: 1 | C12: 9 | D12: 0 | E12: 0 | F12: 0 | G12: 1 | H12: 1 | I12: 0 | J12: 2 | K12: =$P$13+$Q$13*C12+$S$13*D12+$T$13*E12+$U$13*F12+$V$13*G12+$W$13*H12+$X$13*I12 -> 1.6385281 | L12: =J12-K12 -> 0.36147192 | M12: =L12^2 -> 0.13066195 | O12: Коэффициенты модели (2.3) | P12: A0 | Q12: A1 | R12: K1 | S12: K2 | T12: K3 | U12: K4 | V12: Pr | W12: Cv | X12: CD
A13: 9 | B13: 1 | C13: 10 | D13: 1 | E13: 0 | F13: 0 | G13: 2 | H13: 4 | I13: 5 | J13: 5 | K13: =$P$13+$Q$13*C13+$S$13*D13+$T$13*E13+$U$13*F13+$V$13*G13+$W$13*H13+$X$13*I13 -> 5.1101683 | L13: =J13-K13 -> -0.11016826 | M13: =L13^2 -> 0.012137045 | O13: значение | P13: =W6 -> 0.68522234 | Q13: =V6 -> 0.007915906 | R13: 0 | S13: =U6 -> -0.27773881 | T13: =T6 -> -0.033986403 | U13: =S6 -> 0.93609749 | V13: =R6 -> 0.55701626 | W13: =Q6 -> 0.32504632 | X13: =P6 -> 0.44186157
A14: 10 | B14: 1 | C14: 11 | D14: 0 | E14: 1 | F14: 0 | G14: 1 | H14: 5 | I14: 2 | J14: 4 | K14: =$P$13+$Q$13*C14+$S$13*D14+$T$13*E14+$U$13*F14+$V$13*G14+$W$13*H14+$X$13*I14 -> 3.8042819 | L14: =J14-K14 -> 0.19571808 | M14: =L14^2 -> 0.038305569 | O14: ст. ошибка | P14: =W7 -> 0.45863325 | Q14: =V7 -> 0.014757941 | R14: — | S14: =U7 -> 0.53744489 | T14: =T7 -> 0.46892259 | U14: =S7 -> 0.44123865 | V14: =R7 -> 0.13170847 | W14: =Q7 -> 0.12190626 | X14: =P7 -> 0.14965811
A15: 11 | B15: 1 | C15: 12 | D15: 0 | E15: 0 | F15: 1 | G15: 4 | H15: 1 | I15: 3 | J15: 5 | K15: =$P$13+$Q$13*C15+$S$13*D15+$T$13*E15+$U$13*F15+$V$13*G15+$W$13*H15+$X$13*I15 -> 5.5950068 | L15: =J15-K15 -> -0.59500678 | M15: =L15^2 -> 0.35403307 | O15: t-статистика | P15: =P13/P14 -> 1.4940529 | Q15: =Q13/Q14 -> 0.53638282 | R15: — | S15: =S13/S14 -> -0.51677635 | T15: =T13/T14 -> -0.072477641 | U15: =U13/U14 -> 2.121522 | V15: =V13/V14 -> 4.2291604 | W15: =W13/W14 -> 2.6663629 | X15: =X13/X14 -> 2.9524732
A16: 12 | B16: 1 | C16: 13 | D16: 0 | E16: 0 | F16: 0 | G16: 2 | H16: 0 | I16: 0 | J16: 2 | K16: =$P$13+$Q$13*C16+$S$13*D16+$T$13*E16+$U$13*F16+$V$13*G16+$W$13*H16+$X$13*I16 -> 1.9021616 | L16: =J16-K16 -> 0.09783836 | M16: =L16^2 -> 0.0095723447 | O16: Критическое t (α = 0,05; df = 27): | W16: =_xlfn.T.INV.2T(0.05,27) -> 2.0518305
A17: 13 | B17: 1 | C17: 14 | D17: 1 | E17: 0 | F17: 0 | G17: 4 | H17: 5 | I17: 5 | J17: 6 | K17: =$P$13+$Q$13*C17+$S$13*D17+$T$13*E17+$U$13*F17+$V$13*G17+$W$13*H17+$X$13*I17 -> 6.5809107 | L17: =J17-K17 -> -0.58091072 | M17: =L17^2 -> 0.33745727
A18: 14 | B18: 1 | C18: 15 | D18: 0 | E18: 1 | F18: 0 | G18: 2 | H18: 4 | I18: 4 | J18: 6 | K18: =$P$13+$Q$13*C18+$S$13*D18+$T$13*E18+$U$13*F18+$V$13*G18+$W$13*H18+$X$13*I18 -> 4.9516386 | L18: =J18-K18 -> 1.0483614 | M18: =L18^2 -> 1.0990616 | O18: Проверка: решение нормальных уравнений b = (XᵀX)⁻¹·Xᵀy (МУМНОЖ, МОБР, ТРАНСП)
A19: 15 | B19: 1 | C19: 16 | D19: 0 | E19: 0 | F19: 1 | G19: 5 | H19: 5 | I19: 2 | J19: 7 | K19: =$P$13+$Q$13*C19+$S$13*D19+$T$13*E19+$U$13*F19+$V$13*G19+$W$13*H19+$X$13*I19 -> 7.0420104 | L19: =J19-K19 -> -0.042010375 | M19: =L19^2 -> 0.0017648716 | O19: A0 | P19: {=MMULT(MINVERSE(MMULT(TRANSPOSE(B5:I39),B5:I39)),MMULT(TRANSPOSE(B5:I39),J5:J39))} -> 0.68522234
A20: 16 | B20: 1 | C20: 17 | D20: 0 | E20: 0 | F20: 0 | G20: 4 | H20: 4 | I20: 4 | J20: 5 | K20: =$P$13+$Q$13*C20+$S$13*D20+$T$13*E20+$U$13*F20+$V$13*G20+$W$13*H20+$X$13*I20 -> 6.1154894 | L20: =J20-K20 -> -1.1154894 | M20: =L20^2 -> 1.2443165 | O20: A1 | P20: 0.007915906
A21: 17 | B21: 1 | C21: 18 | D21: 1 | E21: 0 | F21: 0 | G21: 2 | H21: 2 | I21: 3 | J21: 3 | K21: =$P$13+$Q$13*C21+$S$13*D21+$T$13*E21+$U$13*F21+$V$13*G21+$W$13*H21+$X$13*I21 -> 3.6396797 | L21: =J21-K21 -> -0.63967972 | M21: =L21^2 -> 0.40919014 | O21: K2 | P21: -0.27773881
A22: 18 | B22: 1 | C22: 19 | D22: 0 | E22: 1 | F22: 0 | G22: 2 | H22: 3 | I22: 2 | J22: 4 | K22: =$P$13+$Q$13*C22+$S$13*D22+$T$13*E22+$U$13*F22+$V$13*G22+$W$13*H22+$X$13*I22 -> 3.7745328 | L22: =J22-K22 -> 0.22546722 | M22: =L22^2 -> 0.050835467 | O22: K3 | P22: -0.033986403
A23: 19 | B23: 1 | C23: 20 | D23: 0 | E23: 0 | F23: 1 | G23: 4 | H23: 3 | I23: 1 | J23: 6 | K23: =$P$13+$Q$13*C23+$S$13*D23+$T$13*E23+$U$13*F23+$V$13*G23+$W$13*H23+$X$13*I23 -> 5.4247035 | L23: =J23-K23 -> 0.57529647 | M23: =L23^2 -> 0.33096603 | O23: K4 | P23: 0.93609749
A24: 20 | B24: 1 | C24: 21 | D24: 0 | E24: 0 | F24: 0 | G24: 4 | H24: 4 | I24: 3 | J24: 6 | K24: =$P$13+$Q$13*C24+$S$13*D24+$T$13*E24+$U$13*F24+$V$13*G24+$W$13*H24+$X$13*I24 -> 5.7052914 | L24: =J24-K24 -> 0.29470859 | M24: =L24^2 -> 0.086853154 | O24: Pr | P24: 0.55701626
A25: 21 | B25: 1 | C25: 22 | D25: 1 | E25: 0 | F25: 0 | G25: 3 | H25: 7 | I25: 6 | J25: 7 | K25: =$P$13+$Q$13*C25+$S$13*D25+$T$13*E25+$U$13*F25+$V$13*G25+$W$13*H25+$X$13*I25 -> 7.1791759 | L25: =J25-K25 -> -0.17917592 | M25: =L25^2 -> 0.032104012 | O25: Cv | P25: 0.32504632
A26: 22 | B26: 1 | C26: 23 | D26: 0 | E26: 1 | F26: 0 | G26: 4 | H26: 6 | I26: 5 | J26: 7 | K26: =$P$13+$Q$13*C26+$S$13*D26+$T$13*E26+$U$13*F26+$V$13*G26+$W$13*H26+$X$13*I26 -> 7.2209526 | L26: =J26-K26 -> -0.22095261 | M26: =L26^2 -> 0.048820054 | O26: CD | P26: 0.44186157
A27: 23 | B27: 1 | C27: 24 | D27: 0 | E27: 0 | F27: 1 | G27: 3 | H27: 3 | I27: 2 | J27: 3 | K27: =$P$13+$Q$13*C27+$S$13*D27+$T$13*E27+$U$13*F27+$V$13*G27+$W$13*H27+$X$13*I27 -> 5.3412125 | L27: =J27-K27 -> -2.3412125 | M27: =L27^2 -> 5.4812758
A28: 24 | B28: 1 | C28: 25 | D28: 0 | E28: 0 | F28: 0 | G28: 1 | H28: 1 | I28: 0 | J28: 1 | K28: =$P$13+$Q$13*C28+$S$13*D28+$T$13*E28+$U$13*F28+$V$13*G28+$W$13*H28+$X$13*I28 -> 1.7651826 | L28: =J28-K28 -> -0.76518257 | M28: =L28^2 -> 0.58550437 | O28: Качество модели
A29: 25 | B29: 1 | C29: 26 | D29: 1 | E29: 0 | F29: 0 | G29: 0 | H29: 1 | I29: 1 | J29: 1 | K29: =$P$13+$Q$13*C29+$S$13*D29+$T$13*E29+$U$13*F29+$V$13*G29+$W$13*H29+$X$13*I29 -> 1.380205 | L29: =J29-K29 -> -0.38020498 | M29: =L29^2 -> 0.14455583 | O29: n (наблюдений) | P29: =COUNT(J5:J39) -> 35
A30: 26 | B30: 1 | C30: 27 | D30: 0 | E30: 1 | F30: 0 | G30: 3 | H30: 1 | I30: 3 | J30: 4 | K30: =$P$13+$Q$13*C30+$S$13*D30+$T$13*E30+$U$13*F30+$V$13*G30+$W$13*H30+$X$13*I30 -> 4.1866452 | L30: =J30-K30 -> -0.18664522 | M30: =L30^2 -> 0.034836438 | O30: k (параметров) | P30: 8
A31: 27 | B31: 1 | C31: 28 | D31: 0 | E31: 0 | F31: 1 | G31: 1 | H31: 0 | I31: 1 | J31: 2 | K31: =$P$13+$Q$13*C31+$S$13*D31+$T$13*E31+$U$13*F31+$V$13*G31+$W$13*H31+$X$13*I31 -> 2.841843 | L31: =J31-K31 -> -0.84184304 | M31: =L31^2 -> 0.7086997 | O31: SSE = ΣE² | P31: =M40 -> 20.368905
A32: 28 | B32: 1 | C32: 29 | D32: 0 | E32: 0 | F32: 0 | G32: 2 | H32: 1 | I32: 2 | J32: 4 | K32: =$P$13+$Q$13*C32+$S$13*D32+$T$13*E32+$U$13*F32+$V$13*G32+$W$13*H32+$X$13*I32 -> 3.2375856 | L32: =J32-K32 -> 0.7624144 | M32: =L32^2 -> 0.58127571 | O32: SST = ДИСП.Σ(Y) | P32: =DEVSQ(J5:J39) -> 130.17143
A33: 29 | B33: 1 | C33: 30 | D33: 1 | E33: 0 | F33: 0 | G33: 1 | H33: 4 | I33: 3 | J33: 4 | K33: =$P$13+$Q$13*C33+$S$13*D33+$T$13*E33+$U$13*F33+$V$13*G33+$W$13*H33+$X$13*I33 -> 3.827747 | L33: =J33-K33 -> 0.17225303 | M33: =L33^2 -> 0.029671105 | O33: R² = 1 − SSE/SST | P33: =1-P31/P32 -> 0.84352246
A34: 30 | B34: 1 | C34: 31 | D34: 0 | E34: 1 | F34: 0 | G34: 7 | H34: 4 | I34: 4 | J34: 8 | K34: =$P$13+$Q$13*C34+$S$13*D34+$T$13*E34+$U$13*F34+$V$13*G34+$W$13*H34+$X$13*I34 -> 7.8633744 | L34: =J34-K34 -> 0.13662558 | M34: =L34^2 -> 0.01866655 | O34: R (множественный) | P34: =SQRT(P33) -> 0.91843479
A35: 31 | B35: 1 | C35: 32 | D35: 0 | E35: 0 | F35: 1 | G35: 1 | H35: 1 | I35: 1 | J35: 4 | K35: =$P$13+$Q$13*C35+$S$13*D35+$T$13*E35+$U$13*F35+$V$13*G35+$W$13*H35+$X$13*I35 -> 3.198553 | L35: =J35-K35 -> 0.80144702 | M35: =L35^2 -> 0.64231733 | O35: F-статистика | P35: =(P32-P31)/(P30-1)/(P31/(P29-P30)) -> 20.792675
A36: 32 | B36: 1 | C36: 33 | D36: 0 | E36: 0 | F36: 0 | G36: 1 | H36: 1 | I36: 3 | J36: 4 | K36: =$P$13+$Q$13*C36+$S$13*D36+$T$13*E36+$U$13*F36+$V$13*G36+$W$13*H36+$X$13*I36 -> 3.1540945 | L36: =J36-K36 -> 0.84590546 | M36: =L36^2 -> 0.71555604 | O36: p-значение F | P36: =_xlfn.F.DIST.RT(P35,P30-1,P29-P30) -> 2.4537783e-09
A37: 33 | B37: 1 | C37: 34 | D37: 1 | E37: 0 | F37: 0 | G37: 3 | H37: 2 | I37: 5 | J37: 6 | K37: =$P$13+$Q$13*C37+$S$13*D37+$T$13*E37+$U$13*F37+$V$13*G37+$W$13*H37+$X$13*I37 -> 5.2070736 | L37: =J37-K37 -> 0.79292638 | M37: =L37^2 -> 0.62873224 | O37: СКО остатков s | P37: =SQRT(P31/(P29-P30)) -> 0.86856427
A38: 34 | B38: 1 | C38: 35 | D38: 0 | E38: 1 | F38: 0 | G38: 3 | H38: 5 | I38: 5 | J38: 6 | K38: =$P$13+$Q$13*C38+$S$13*D38+$T$13*E38+$U$13*F38+$V$13*G38+$W$13*H38+$X$13*I38 -> 6.4338809 | L38: =J38-K38 -> -0.4338809 | M38: =L38^2 -> 0.18825263 | O38: Среднее E² (как М37 у автора) | P38: =P31/P29 -> 0.58196871
A39: 35 | B39: 1 | C39: 36 | D39: 0 | E39: 0 | F39: 1 | G39: 3 | H39: 1 | I39: 2 | J39: 5 | K39: =$P$13+$Q$13*C39+$S$13*D39+$T$13*E39+$U$13*F39+$V$13*G39+$W$13*H39+$X$13*I39 -> 4.7861107 | L39: =J39-K39 -> 0.2138893 | M39: =L39^2 -> 0.045748635
I40: Σ | J40: =SUM(J5:J39) -> 162 | K40: =SUM(K5:K39) -> 162 | L40: =SUM(L5:L39) -> -3.5083048e-14 | M40: =SUM(M5:M39) -> 20.368905 | O40: Коэффициенты, опубликованные в ВКР (рис. 3.2, строка 42)
P41: A0 | Q41: A1 | R41: K1 | S41: K2 | T41: K3 | U41: K4 | V41: Pr | W41: Cv | X41: CD
...

Sheet МНК_172
A1: Чувствительность: МНК по всем 172 ДТП (без исключения двух январских ДТП 2009 г.)
A2: Отличается от листа МНК_STATS19 только первым кварталом 2009 г. (Y = 3 вместо 1)
A4: № | B4: 1 | C4: t | D4: K2 | E4: K3 | F4: K4 | G4: Pr | H4: Cv | I4: CD | J4: Y | K4: Ŷ | L4: E = Y − Ŷ | M4: E² | O4: ЛИНЕЙН(Y; t…CD; ИСТИНА; ИСТИНА) — порядок коэффициентов обратный
A5: 1 | B5: 1 | C5: =Таблица_наблюдений!A5 -> 1 | D5: =Таблица_наблюдений!I5 -> 0 | E5: =Таблица_наблюдений!J5 -> 0 | F5: =Таблица_наблюдений!K5 -> 0 | G5: =Таблица_наблюдений!U5 -> 2 | H5: =Таблица_наблюдений!V5 -> 1 | I5: =Таблица_наблюдений!W5 -> 1 | J5: =Таблица_наблюдений!T5 -> 3 | K5: =$P$13+$Q$13*C5+$S$13*D5+$T$13*E5+$U$13*F5+$V$13*G5+$W$13*H5+$X$13*I5 -> 3.2401433 | L5: =J5-K5 -> -0.24014332 | M5: =L5^2 -> 0.057668816 | P5: CD | Q5: Cv | R5: Pr | S5: K4 | T5: K3 | U5: K2 | V5: A1 | W5: A0
A6: 2 | B6: 1 | C6: =Таблица_наблюдений!A6 -> 2 | D6: =Таблица_наблюдений!I6 -> 1 | E6: =Таблица_наблюдений!J6 -> 0 | F6: =Таблица_наблюдений!K6 -> 0 | G6: =Таблица_наблюдений!U6 -> 3 | H6: =Таблица_наблюдений!V6 -> 6 | I6: =Таблица_наблюдений!W6 -> 7 | J6: =Таблица_наблюдений!T6 -> 9 | K6: =$P$13+$Q$13*C6+$S$13*D6+$T$13*E6+$U$13*F6+$V$13*G6+$W$13*H6+$X$13*I6 -> 8.0195995 | L6: =J6-K6 -> 0.98040048 | M6: =L6^2 -> 0.9611851 | O6: коэффициент | P6: {=IFERROR(LINEST(J5:J39,C5:I39,TRUE,TRUE),"")} -> 0.52615383 | Q6: 0.33170631 | R6: 0.53471338 | S6: 1.0883331 | T6: -0.18341768 | U6: -0.55479693 | V6: -0.015914748 | W6: 1.3287712
A7: 3 | B7: 1 | C7: =Таблица_наблюдений!A7 -> 3 | D7: =Таблица_наблюдений!I7 -> 0 | E7: =Таблица_наблюдений!J7 -> 1 | F7: =Таблица_наблюдений!K7 -> 0 | G7: =Таблица_наблюдений!U7 -> 2 | H7: =Таблица_наблюдений!V7 -> 2 | I7: =Таблица_наблюдений!W7 -> 3 | J7: =Таблица_наблюдений!T7 -> 3 | K7: =$P$13+$Q$13*C7+$S$13*D7+$T$13*E7+$U$13*F7+$V$13*G7+$W$13*H7+$X$13*I7 -> 4.4089101 | L7: =J7-K7 -> -1.4089101 | M7: =L7^2 -> 1.9850277 | O7: ст. ошибка | P7: 0.21273743 | Q7: 0.17048063 | R7: 0.19980897 | S7: 0.58752793 | T7: 0.64020241 | U7: 0.74558682 | V7: 0.020135366 | W7: 0.6878082
A8: 4 | B8: 1 | C8: =Таблица_наблюдений!A8 -> 4 | D8: =Таблица_наблюдений!I8 -> 0 | E8: =Таблица_наблюдений!J8 -> 0 | F8: =Таблица_наблюдений!K8 -> 1 | G8: =Таблица_наблюдений!U8 -> 3 | H8: =Таблица_наблюдений!V8 -> 1 | I8: =Таблица_наблюдений!W8 -> 2 | J8: =Таблица_наблюдений!T8 -> 7 | K8: =$P$13+$Q$13*C8+$S$13*D8+$T$13*E8+$U$13*F8+$V$13*G8+$W$13*H8+$X$13*I8 -> 5.3415994 | L8: =J8-K8 -> 1.6584006 | M8: =L8^2 -> 2.7502924 | O8: R² | s | P8: 0.73090422 | Q8: 1.1843628
A9: 5 | B9: 1 | C9: =Таблица_наблюдений!A9 -> 5 | D9: =Таблица_наблюдений!I9 -> 0 | E9: =Таблица_наблюдений!J9 -> 0 | F9: =Таблица_наблюдений!K9 -> 0 | G9: =Таблица_наблюдений!U9 -> 2 | H9: =Таблица_наблюдений!V9 -> 4 | I9: =Таблица_наблюдений!W9 -> 3 | J9: =Таблица_наблюдений!T9 -> 7 | K9: =$P$13+$Q$13*C9+$S$13*D9+$T$13*E9+$U$13*F9+$V$13*G9+$W$13*H9+$X$13*I9 -> 5.2239109 | L9: =J9-K9 -> 1.7760891 | M9: =L9^2 -> 3.1544925 | O9: F | df | P9: 10.476575 | Q9: 27
A10: 6 | B10: 1 | C10: =Таблица_наблюдений!A10 -> 6 | D10: =Таблица_наблюдений!I10 -> 1 | E10: =Таблица_наблюдений!J10 -> 0 | F10: =Таблица_наблюдений!K10 -> 0 | G10: =Таблица_наблюдений!U10 -> 2 | H10: =Таблица_наблюдений!V10 -> 7 | I10: =Таблица_наблюдений!W10 -> 7 | J10: =Таблица_наблюдений!T10 -> 8 | K10: =$P$13+$Q$13*C10+$S$13*D10+$T$13*E10+$U$13*F10+$V$13*G10+$W$13*H10+$X$13*I10 -> 7.7529335 | L10: =J10-K10 -> 0.24706654 | M10: =L10^2 -> 0.061041877 | O10: SSR | SSE | P10: 102.86955 | Q10: 37.873308
A11: 7 | B11: 1 | C11: =Таблица_наблюдений!A12 -> 8 | D11: =Таблица_наблюдений!I12 -> 0 | E11: =Таблица_наблюдений!J12 -> 0 | F11: =Таблица_наблюдений!K12 -> 1 | G11: =Таблица_наблюдений!U12 -> 4 | H11: =Таблица_наблюдений!V12 -> 1 | I11: =Таблица_наблюдений!W12 -> 0 | J11: =Таблица_наблюдений!T12 -> 6 | K11: =$P$13+$Q$13*C11+$S$13*D11+$T$13*E11+$U$13*F11+$V$13*G11+$W$13*H11+$X$13*I11 -> 4.7603462 | L11: =J11-K11 -> 1.2396538 | M11: =L11^2 -> 1.5367416
A12: 8 | B12: 1 | C12: =Таблица_наблюдений!A13 -> 9 | D12: =Таблица_наблюдений!I13 -> 0 | E12: =Таблица_наблюдений!J13 -> 0 | F12: =Таблица_наблюдений!K13 -> 0 | G12: =Таблица_наблюдений!U13 -> 1 | H12: =Таблица_наблюдений!V13 -> 1 | I12: =Таблица_наблюдений!W13 -> 0 | J12: =Таблица_наблюдений!T13 -> 2 | K12: =$P$13+$Q$13*C12+$S$13*D12+$T$13*E12+$U$13*F12+$V$13*G12+$W$13*H12+$X$13*I12 -> 2.0519581 | L12: =J12-K12 -> -0.051958133 | M12: =L12^2 -> 0.0026996476 | O12: Коэффициенты модели (2.3) | P12: A0 | Q12: A1 | R12: K1 | S12: K2 | T12: K3 | U12: K4 | V12: Pr | W12: Cv | X12: CD
A13: 9 | B13: 1 | C13: =Таблица_наблюдений!A14 -> 10 | D13: =Таблица_наблюдений!I14 -> 1 | E13: =Таблица_наблюдений!J14 -> 0 | F13: =Таблица_наблюдений!K14 -> 0 | G13: =Таблица_наблюдений!U14 -> 2 | H13: =Таблица_наблюдений!V14 -> 4 | I13: =Таблица_наблюдений!W14 -> 5 | J13: =Таблица_наблюдений!T14 -> 5 | K13: =$P$13+$Q$13*C13+$S$13*D13+$T$13*E13+$U$13*F13+$V$13*G13+$W$13*H13+$X$13*I13 -> 5.6418479 | L13: =J13-K13 -> -0.64184789 | M13: =L13^2 -> 0.41196871 | O13: значение | P13: =W6 -> 1.3287712 | Q13: =V6 -> -0.015914748 | R13: 0 | S13: =U6 -> -0.55479693 | T13: =T6 -> -0.18341768 | U13: =S6 -> 1.0883331 | V13: =R6 -> 0.53471338 | W13: =Q6 -> 0.33170631 | X13: =P6 -> 0.52615383
A14: 10 | B14: 1 | C14: =Таблица_наблюдений!A15 -> 11 | D14: =Таблица_наблюдений!I15 -> 0 | E14: =Таблица_наблюдений!J15 -> 1 | F14: =Таблица_наблюдений!K15 -> 0 | G14: =Таблица_наблюдений!U15 -> 1 | H14: =Таблица_наблюдений!V15 -> 5 | I14: =Таблица_наблюдений!W15 -> 2 | J14: =Таблица_наблюдений!T15 -> 5 | K14: =$P$13+$Q$13*C14+$S$13*D14+$T$13*E14+$U$13*F14+$V$13*G14+$W$13*H14+$X$13*I14 -> 4.2158438 | L14: =J14-K14 -> 0.78415616 | M14: =L14^2 -> 0.61490089 | O14: ст. ошибка | P14: =W7 -> 0.6878082 | Q14: =V7 -> 0.020135366 | R14: — | S14: =U7 -> 0.74558682 | T14: =T7 -> 0.64020241 | U14: =S7 -> 0.58752793 | V14: =R7 -> 0.19980897 | W14: =Q7 -> 0.17048063 | X14: =P7 -> 0.21273743
A15: 11 | B15: 1 | C15: =Таблица_наблюдений!A16 -> 12 | D15: =Таблица_наблюдений!I16 -> 0 | E15: =Таблица_наблюдений!J16 -> 0 | F15: =Таблица_наблюдений!K16 -> 1 | G15: =Таблица_наблюдений!U16 -> 4 | H15: =Таблица_наблюдений!V16 -> 1 | I15: =Таблица_наблюдений!W16 -> 3 | J15: =Таблица_наблюдений!T16 -> 5 | K15: =$P$13+$Q$13*C15+$S$13*D15+$T$13*E15+$U$13*F15+$V$13*G15+$W$13*H15+$X$13*I15 -> 6.2751487 | L15: =J15-K15 -> -1.2751487 | M15: =L15^2 -> 1.6260041 | O15: t-статистика | P15: =P13/P14 -> 1.931892 | Q15: =Q13/Q14 -> -0.79038782 | R15: — | S15: =S13/S14 -> -0.74410775 | T15: =T13/T14 -> -0.28649951 | U15: =U13/U14 -> 1.8523939 | V15: =V13/V14 -> 2.676123 | W15: =W13/W14 -> 1.9457126 | X15: =X13/X14 -> 2.4732546
A16: 12 | B16: 1 | C16: =Таблица_наблюдений!A17 -> 13 | D16: =Таблица_наблюдений!I17 -> 0 | E16: =Таблица_наблюдений!J17 -> 0 | F16: =Таблица_наблюдений!K17 -> 0 | G16: =Таблица_наблюдений!U17 -> 4 | H16: =Таблица_наблюдений!V17 -> 2 | I16: =Таблица_наблюдений!W17 -> 2 | J16: =Таблица_наблюдений!T17 -> 4 | K16: =$P$13+$Q$13*C16+$S$13*D16+$T$13*E16+$U$13*F16+$V$13*G16+$W$13*H16+$X$13*I16 -> 4.9764532 | L16: =J16-K16 -> -0.97645324 | M16: =L16^2 -> 0.95346092 | O16: Критическое t (α = 0,05; df = 27): | W16: =_xlfn.T.INV.2T(0.05,27) -> 2.0518305
